2019-09-22 22:29:39,694 - INFO - C:\Users\bhavya\Desktop\sad_final\sad_project\garbage_project\garbage_app\views.py changed, reloading.
2019-09-22 22:29:41,050 - DEBUG - Hello world 
2019-09-22 22:30:24,534 - INFO - C:\Users\bhavya\Desktop\sad_final\sad_project\garbage_project\garbage_app\views.py changed, reloading.
2019-09-22 22:44:17,593 - INFO - C:\Users\bhavya\Desktop\sad_final\sad_project\garbage_project\garbage_app\views.py changed, reloading.
2019-09-22 22:44:34,371 - INFO - C:\Users\bhavya\Desktop\sad_final\sad_project\garbage_project\garbage_app\views.py changed, reloading.
2019-09-22 22:45:51,705 - INFO - C:\Users\bhavya\Desktop\sad_final\sad_project\garbage_project\garbage_app\views.py changed, reloading.
2019-09-22 22:46:09,915 - ERROR - Internal Server Error: /user/register/
Traceback (most recent call last):
  File "C:\Users\bhavya\Anaconda3\envs\myenv1\lib\site-packages\django\core\handlers\exception.py", line 34, in inner
    response = get_response(request)
  File "C:\Users\bhavya\Anaconda3\envs\myenv1\lib\site-packages\django\core\handlers\base.py", line 115, in _get_response
    response = self.process_exception_by_middleware(e, request)
  File "C:\Users\bhavya\Anaconda3\envs\myenv1\lib\site-packages\django\core\handlers\base.py", line 113, in _get_response
    response = wrapped_callback(request, *callback_args, **callback_kwargs)
  File "C:\Users\bhavya\Anaconda3\envs\myenv1\lib\site-packages\django\views\decorators\csrf.py", line 54, in wrapped_view
    return view_func(*args, **kwargs)
  File "C:\Users\bhavya\Anaconda3\envs\myenv1\lib\site-packages\django\views\generic\base.py", line 71, in view
    return self.dispatch(request, *args, **kwargs)
  File "C:\Users\bhavya\Anaconda3\envs\myenv1\lib\site-packages\rest_framework\views.py", line 497, in dispatch
    response = self.handle_exception(exc)
  File "C:\Users\bhavya\Anaconda3\envs\myenv1\lib\site-packages\rest_framework\views.py", line 457, in handle_exception
    self.raise_uncaught_exception(exc)
  File "C:\Users\bhavya\Anaconda3\envs\myenv1\lib\site-packages\rest_framework\views.py", line 468, in raise_uncaught_exception
    raise exc
  File "C:\Users\bhavya\Anaconda3\envs\myenv1\lib\site-packages\rest_framework\views.py", line 494, in dispatch
    response = handler(request, *args, **kwargs)
  File "C:\Users\bhavya\Anaconda3\envs\myenv1\lib\site-packages\rest_framework\decorators.py", line 50, in handler
    return func(*args, **kwargs)
  File "C:\Users\bhavya\Desktop\sad_final\sad_project\garbage_project\garbage_app\views.py", line 77, in Register_Garbage_User
    email=request.data[0]["email_id"]
KeyError: 0
2019-09-22 22:48:06,594 - ERROR - Internal Server Error: /user/register/
Traceback (most recent call last):
  File "C:\Users\bhavya\Anaconda3\envs\myenv1\lib\site-packages\django\core\handlers\exception.py", line 34, in inner
    response = get_response(request)
  File "C:\Users\bhavya\Anaconda3\envs\myenv1\lib\site-packages\django\core\handlers\base.py", line 115, in _get_response
    response = self.process_exception_by_middleware(e, request)
  File "C:\Users\bhavya\Anaconda3\envs\myenv1\lib\site-packages\django\core\handlers\base.py", line 113, in _get_response
    response = wrapped_callback(request, *callback_args, **callback_kwargs)
  File "C:\Users\bhavya\Anaconda3\envs\myenv1\lib\site-packages\django\views\decorators\csrf.py", line 54, in wrapped_view
    return view_func(*args, **kwargs)
  File "C:\Users\bhavya\Anaconda3\envs\myenv1\lib\site-packages\django\views\generic\base.py", line 71, in view
    return self.dispatch(request, *args, **kwargs)
  File "C:\Users\bhavya\Anaconda3\envs\myenv1\lib\site-packages\rest_framework\views.py", line 497, in dispatch
    response = self.handle_exception(exc)
  File "C:\Users\bhavya\Anaconda3\envs\myenv1\lib\site-packages\rest_framework\views.py", line 457, in handle_exception
    self.raise_uncaught_exception(exc)
  File "C:\Users\bhavya\Anaconda3\envs\myenv1\lib\site-packages\rest_framework\views.py", line 468, in raise_uncaught_exception
    raise exc
  File "C:\Users\bhavya\Anaconda3\envs\myenv1\lib\site-packages\rest_framework\views.py", line 494, in dispatch
    response = handler(request, *args, **kwargs)
  File "C:\Users\bhavya\Anaconda3\envs\myenv1\lib\site-packages\rest_framework\decorators.py", line 50, in handler
    return func(*args, **kwargs)
  File "C:\Users\bhavya\Desktop\sad_final\sad_project\garbage_project\garbage_app\views.py", line 77, in Register_Garbage_User
    email=request.data[0]["email_id"]
KeyError: 0
2019-09-22 22:50:32,632 - INFO - C:\Users\bhavya\Desktop\sad_final\sad_project\garbage_project\garbage_app\views.py changed, reloading.
2019-09-22 22:50:35,729 - ERROR - Internal Server Error: /user/register/
Traceback (most recent call last):
  File "C:\Users\bhavya\Anaconda3\envs\myenv1\lib\site-packages\django\core\handlers\exception.py", line 34, in inner
    response = get_response(request)
  File "C:\Users\bhavya\Anaconda3\envs\myenv1\lib\site-packages\django\core\handlers\base.py", line 115, in _get_response
    response = self.process_exception_by_middleware(e, request)
  File "C:\Users\bhavya\Anaconda3\envs\myenv1\lib\site-packages\django\core\handlers\base.py", line 113, in _get_response
    response = wrapped_callback(request, *callback_args, **callback_kwargs)
  File "C:\Users\bhavya\Anaconda3\envs\myenv1\lib\site-packages\django\views\decorators\csrf.py", line 54, in wrapped_view
    return view_func(*args, **kwargs)
  File "C:\Users\bhavya\Anaconda3\envs\myenv1\lib\site-packages\django\views\generic\base.py", line 71, in view
    return self.dispatch(request, *args, **kwargs)
  File "C:\Users\bhavya\Anaconda3\envs\myenv1\lib\site-packages\rest_framework\views.py", line 497, in dispatch
    response = self.handle_exception(exc)
  File "C:\Users\bhavya\Anaconda3\envs\myenv1\lib\site-packages\rest_framework\views.py", line 457, in handle_exception
    self.raise_uncaught_exception(exc)
  File "C:\Users\bhavya\Anaconda3\envs\myenv1\lib\site-packages\rest_framework\views.py", line 468, in raise_uncaught_exception
    raise exc
  File "C:\Users\bhavya\Anaconda3\envs\myenv1\lib\site-packages\rest_framework\views.py", line 494, in dispatch
    response = handler(request, *args, **kwargs)
  File "C:\Users\bhavya\Anaconda3\envs\myenv1\lib\site-packages\rest_framework\decorators.py", line 50, in handler
    return func(*args, **kwargs)
  File "C:\Users\bhavya\Desktop\sad_final\sad_project\garbage_project\garbage_app\views.py", line 77, in Register_Garbage_User
    email=request.data[0]["email_id"]
KeyError: 0
2019-09-22 22:55:34,210 - DEBUG - aman@gmailaa.com
2019-09-22 22:55:34,217 - DEBUG - Garbage_User object (3)
2019-09-22 23:06:45,741 - INFO - C:\Users\bhavya\Desktop\sad_final\sad_project\garbage_project\garbage_app\models.py changed, reloading.
2019-09-22 23:14:36,643 - INFO - C:\Users\bhavya\Desktop\sad_final\sad_project\garbage_project\garbage_app\views.py changed, reloading.
2019-09-23 17:23:54,407 - INFO - C:\Users\bhavya\Desktop\sad_final\sad_project\garbage_project\garbage_project\urls.py changed, reloading.
2019-09-23 17:26:53,326 - INFO - C:\Users\bhavya\Desktop\sad_final\sad_project\garbage_project\garbage_project\urls.py changed, reloading.
2019-09-23 17:27:04,719 - INFO - C:\Users\bhavya\Desktop\sad_final\sad_project\garbage_project\garbage_app\views.py changed, reloading.
2019-09-23 17:29:34,090 - WARNING - Bad Request: /postAPI/
2019-09-23 18:10:10,022 - INFO - C:\Users\bhavya\Desktop\sad_final\sad_project\garbage_project\garbage_app\views.py changed, reloading.
2019-09-23 18:11:01,232 - INFO - C:\Users\bhavya\Desktop\sad_final\sad_project\garbage_project\garbage_app\views.py changed, reloading.
2019-09-23 18:11:09,961 - INFO - C:\Users\bhavya\Desktop\sad_final\sad_project\garbage_project\garbage_app\views.py changed, reloading.
2019-09-23 18:12:45,224 - ERROR - Internal Server Error: /user/register
Traceback (most recent call last):
  File "C:\Users\bhavya\Anaconda3\envs\myenv1\lib\site-packages\django\core\handlers\exception.py", line 34, in inner
    response = get_response(request)
  File "C:\Users\bhavya\Anaconda3\envs\myenv1\lib\site-packages\django\utils\deprecation.py", line 93, in __call__
    response = self.process_request(request)
  File "C:\Users\bhavya\Anaconda3\envs\myenv1\lib\site-packages\django\middleware\common.py", line 53, in process_request
    path = self.get_full_path_with_slash(request)
  File "C:\Users\bhavya\Anaconda3\envs\myenv1\lib\site-packages\django\middleware\common.py", line 93, in get_full_path_with_slash
    'url': request.get_host() + new_path,
RuntimeError: You called this URL via POST, but the URL doesn't end in a slash and you have APPEND_SLASH set. Django can't redirect to the slash URL while maintaining POST data. Change your form to point to 127.0.0.1:8000/user/register/ (note the trailing slash), or set APPEND_SLASH=False in your Django settings.
2019-09-23 18:13:36,969 - DEBUG - somi@gmailaa.com
2019-09-23 18:13:37,051 - ERROR - Internal Server Error: /user/register/
Traceback (most recent call last):
  File "C:\Users\bhavya\Anaconda3\envs\myenv1\lib\site-packages\django\core\handlers\exception.py", line 34, in inner
    response = get_response(request)
  File "C:\Users\bhavya\Anaconda3\envs\myenv1\lib\site-packages\django\core\handlers\base.py", line 115, in _get_response
    response = self.process_exception_by_middleware(e, request)
  File "C:\Users\bhavya\Anaconda3\envs\myenv1\lib\site-packages\django\core\handlers\base.py", line 113, in _get_response
    response = wrapped_callback(request, *callback_args, **callback_kwargs)
  File "C:\Users\bhavya\Anaconda3\envs\myenv1\lib\site-packages\django\views\decorators\csrf.py", line 54, in wrapped_view
    return view_func(*args, **kwargs)
  File "C:\Users\bhavya\Anaconda3\envs\myenv1\lib\site-packages\django\views\generic\base.py", line 71, in view
    return self.dispatch(request, *args, **kwargs)
  File "C:\Users\bhavya\Anaconda3\envs\myenv1\lib\site-packages\rest_framework\views.py", line 497, in dispatch
    response = self.handle_exception(exc)
  File "C:\Users\bhavya\Anaconda3\envs\myenv1\lib\site-packages\rest_framework\views.py", line 457, in handle_exception
    self.raise_uncaught_exception(exc)
  File "C:\Users\bhavya\Anaconda3\envs\myenv1\lib\site-packages\rest_framework\views.py", line 468, in raise_uncaught_exception
    raise exc
  File "C:\Users\bhavya\Anaconda3\envs\myenv1\lib\site-packages\rest_framework\views.py", line 494, in dispatch
    response = handler(request, *args, **kwargs)
  File "C:\Users\bhavya\Anaconda3\envs\myenv1\lib\site-packages\rest_framework\decorators.py", line 50, in handler
    return func(*args, **kwargs)
  File "C:\Users\bhavya\Desktop\sad_final\sad_project\garbage_project\garbage_app\views.py", line 80, in Register_Garbage_User
    logging.debug(Garbage_User.objects.get(email_id=email))
  File "C:\Users\bhavya\Anaconda3\envs\myenv1\lib\site-packages\django\db\models\manager.py", line 82, in manager_method
    return getattr(self.get_queryset(), name)(*args, **kwargs)
  File "C:\Users\bhavya\Anaconda3\envs\myenv1\lib\site-packages\django\db\models\query.py", line 408, in get
    self.model._meta.object_name
garbage_app.models.Garbage_User.DoesNotExist: Garbage_User matching query does not exist.
2019-09-23 18:15:38,153 - DEBUG - somi@gmailaa.com
2019-09-23 18:15:38,170 - ERROR - Internal Server Error: /user/register/
Traceback (most recent call last):
  File "C:\Users\bhavya\Anaconda3\envs\myenv1\lib\site-packages\django\core\handlers\exception.py", line 34, in inner
    response = get_response(request)
  File "C:\Users\bhavya\Anaconda3\envs\myenv1\lib\site-packages\django\core\handlers\base.py", line 115, in _get_response
    response = self.process_exception_by_middleware(e, request)
  File "C:\Users\bhavya\Anaconda3\envs\myenv1\lib\site-packages\django\core\handlers\base.py", line 113, in _get_response
    response = wrapped_callback(request, *callback_args, **callback_kwargs)
  File "C:\Users\bhavya\Anaconda3\envs\myenv1\lib\site-packages\django\views\decorators\csrf.py", line 54, in wrapped_view
    return view_func(*args, **kwargs)
  File "C:\Users\bhavya\Anaconda3\envs\myenv1\lib\site-packages\django\views\generic\base.py", line 71, in view
    return self.dispatch(request, *args, **kwargs)
  File "C:\Users\bhavya\Anaconda3\envs\myenv1\lib\site-packages\rest_framework\views.py", line 497, in dispatch
    response = self.handle_exception(exc)
  File "C:\Users\bhavya\Anaconda3\envs\myenv1\lib\site-packages\rest_framework\views.py", line 457, in handle_exception
    self.raise_uncaught_exception(exc)
  File "C:\Users\bhavya\Anaconda3\envs\myenv1\lib\site-packages\rest_framework\views.py", line 468, in raise_uncaught_exception
    raise exc
  File "C:\Users\bhavya\Anaconda3\envs\myenv1\lib\site-packages\rest_framework\views.py", line 494, in dispatch
    response = handler(request, *args, **kwargs)
  File "C:\Users\bhavya\Anaconda3\envs\myenv1\lib\site-packages\rest_framework\decorators.py", line 50, in handler
    return func(*args, **kwargs)
  File "C:\Users\bhavya\Desktop\sad_final\sad_project\garbage_project\garbage_app\views.py", line 80, in Register_Garbage_User
    logging.debug(Garbage_User.objects.get(email_id=email))
  File "C:\Users\bhavya\Anaconda3\envs\myenv1\lib\site-packages\django\db\models\manager.py", line 82, in manager_method
    return getattr(self.get_queryset(), name)(*args, **kwargs)
  File "C:\Users\bhavya\Anaconda3\envs\myenv1\lib\site-packages\django\db\models\query.py", line 408, in get
    self.model._meta.object_name
garbage_app.models.Garbage_User.DoesNotExist: Garbage_User matching query does not exist.
2019-09-23 18:16:50,819 - INFO - C:\Users\bhavya\Desktop\sad_final\sad_project\garbage_project\garbage_app\views.py changed, reloading.
2019-09-23 18:17:20,658 - DEBUG - somi@gmailaa.com
2019-09-23 18:17:20,681 - ERROR - Internal Server Error: /user/register/
Traceback (most recent call last):
  File "C:\Users\bhavya\Anaconda3\envs\myenv1\lib\site-packages\django\core\handlers\exception.py", line 34, in inner
    response = get_response(request)
  File "C:\Users\bhavya\Anaconda3\envs\myenv1\lib\site-packages\django\core\handlers\base.py", line 115, in _get_response
    response = self.process_exception_by_middleware(e, request)
  File "C:\Users\bhavya\Anaconda3\envs\myenv1\lib\site-packages\django\core\handlers\base.py", line 113, in _get_response
    response = wrapped_callback(request, *callback_args, **callback_kwargs)
  File "C:\Users\bhavya\Anaconda3\envs\myenv1\lib\site-packages\django\views\decorators\csrf.py", line 54, in wrapped_view
    return view_func(*args, **kwargs)
  File "C:\Users\bhavya\Anaconda3\envs\myenv1\lib\site-packages\django\views\generic\base.py", line 71, in view
    return self.dispatch(request, *args, **kwargs)
  File "C:\Users\bhavya\Anaconda3\envs\myenv1\lib\site-packages\rest_framework\views.py", line 497, in dispatch
    response = self.handle_exception(exc)
  File "C:\Users\bhavya\Anaconda3\envs\myenv1\lib\site-packages\rest_framework\views.py", line 457, in handle_exception
    self.raise_uncaught_exception(exc)
  File "C:\Users\bhavya\Anaconda3\envs\myenv1\lib\site-packages\rest_framework\views.py", line 468, in raise_uncaught_exception
    raise exc
  File "C:\Users\bhavya\Anaconda3\envs\myenv1\lib\site-packages\rest_framework\views.py", line 494, in dispatch
    response = handler(request, *args, **kwargs)
  File "C:\Users\bhavya\Anaconda3\envs\myenv1\lib\site-packages\rest_framework\decorators.py", line 50, in handler
    return func(*args, **kwargs)
  File "C:\Users\bhavya\Desktop\sad_final\sad_project\garbage_project\garbage_app\views.py", line 80, in Register_Garbage_User
    logging.debug(Garbage_User.objects.get(email_id=email))
  File "C:\Users\bhavya\Anaconda3\envs\myenv1\lib\site-packages\django\db\models\manager.py", line 82, in manager_method
    return getattr(self.get_queryset(), name)(*args, **kwargs)
  File "C:\Users\bhavya\Anaconda3\envs\myenv1\lib\site-packages\django\db\models\query.py", line 408, in get
    self.model._meta.object_name
garbage_app.models.Garbage_User.DoesNotExist: Garbage_User matching query does not exist.
2019-09-23 18:17:44,084 - INFO - C:\Users\bhavya\Desktop\sad_final\sad_project\garbage_project\garbage_app\views.py changed, reloading.
2019-09-23 18:18:25,282 - WARNING - Method Not Allowed: /user/register/
2019-09-23 18:18:51,822 - DEBUG - somi@gmailaa.com
2019-09-23 18:18:51,860 - ERROR - Internal Server Error: /user/register/
Traceback (most recent call last):
  File "C:\Users\bhavya\Anaconda3\envs\myenv1\lib\site-packages\django\core\handlers\exception.py", line 34, in inner
    response = get_response(request)
  File "C:\Users\bhavya\Anaconda3\envs\myenv1\lib\site-packages\django\core\handlers\base.py", line 115, in _get_response
    response = self.process_exception_by_middleware(e, request)
  File "C:\Users\bhavya\Anaconda3\envs\myenv1\lib\site-packages\django\core\handlers\base.py", line 113, in _get_response
    response = wrapped_callback(request, *callback_args, **callback_kwargs)
  File "C:\Users\bhavya\Anaconda3\envs\myenv1\lib\site-packages\django\views\decorators\csrf.py", line 54, in wrapped_view
    return view_func(*args, **kwargs)
  File "C:\Users\bhavya\Anaconda3\envs\myenv1\lib\site-packages\django\views\generic\base.py", line 71, in view
    return self.dispatch(request, *args, **kwargs)
  File "C:\Users\bhavya\Anaconda3\envs\myenv1\lib\site-packages\rest_framework\views.py", line 497, in dispatch
    response = self.handle_exception(exc)
  File "C:\Users\bhavya\Anaconda3\envs\myenv1\lib\site-packages\rest_framework\views.py", line 457, in handle_exception
    self.raise_uncaught_exception(exc)
  File "C:\Users\bhavya\Anaconda3\envs\myenv1\lib\site-packages\rest_framework\views.py", line 468, in raise_uncaught_exception
    raise exc
  File "C:\Users\bhavya\Anaconda3\envs\myenv1\lib\site-packages\rest_framework\views.py", line 494, in dispatch
    response = handler(request, *args, **kwargs)
  File "C:\Users\bhavya\Anaconda3\envs\myenv1\lib\site-packages\rest_framework\decorators.py", line 50, in handler
    return func(*args, **kwargs)
  File "C:\Users\bhavya\Desktop\sad_final\sad_project\garbage_project\garbage_app\views.py", line 80, in Register_Garbage_User
    logging.debug(Garbage_User.objects.get(email_id=email))
  File "C:\Users\bhavya\Anaconda3\envs\myenv1\lib\site-packages\django\db\models\manager.py", line 82, in manager_method
    return getattr(self.get_queryset(), name)(*args, **kwargs)
  File "C:\Users\bhavya\Anaconda3\envs\myenv1\lib\site-packages\django\db\models\query.py", line 408, in get
    self.model._meta.object_name
garbage_app.models.Garbage_User.DoesNotExist: Garbage_User matching query does not exist.
2019-09-23 18:24:59,110 - INFO - C:\Users\bhavya\Desktop\sad_final\sad_project\garbage_project\garbage_app\views.py changed, reloading.
2019-09-23 18:25:59,992 - DEBUG - somi@gmailaa.com
2019-09-23 18:26:00,024 - ERROR - Internal Server Error: /user/register/
Traceback (most recent call last):
  File "C:\Users\bhavya\Anaconda3\envs\myenv1\lib\site-packages\django\core\handlers\exception.py", line 34, in inner
    response = get_response(request)
  File "C:\Users\bhavya\Anaconda3\envs\myenv1\lib\site-packages\django\core\handlers\base.py", line 115, in _get_response
    response = self.process_exception_by_middleware(e, request)
  File "C:\Users\bhavya\Anaconda3\envs\myenv1\lib\site-packages\django\core\handlers\base.py", line 113, in _get_response
    response = wrapped_callback(request, *callback_args, **callback_kwargs)
  File "C:\Users\bhavya\Anaconda3\envs\myenv1\lib\site-packages\django\views\decorators\csrf.py", line 54, in wrapped_view
    return view_func(*args, **kwargs)
  File "C:\Users\bhavya\Anaconda3\envs\myenv1\lib\site-packages\django\views\generic\base.py", line 71, in view
    return self.dispatch(request, *args, **kwargs)
  File "C:\Users\bhavya\Anaconda3\envs\myenv1\lib\site-packages\rest_framework\views.py", line 497, in dispatch
    response = self.handle_exception(exc)
  File "C:\Users\bhavya\Anaconda3\envs\myenv1\lib\site-packages\rest_framework\views.py", line 457, in handle_exception
    self.raise_uncaught_exception(exc)
  File "C:\Users\bhavya\Anaconda3\envs\myenv1\lib\site-packages\rest_framework\views.py", line 468, in raise_uncaught_exception
    raise exc
  File "C:\Users\bhavya\Anaconda3\envs\myenv1\lib\site-packages\rest_framework\views.py", line 494, in dispatch
    response = handler(request, *args, **kwargs)
  File "C:\Users\bhavya\Anaconda3\envs\myenv1\lib\site-packages\rest_framework\decorators.py", line 50, in handler
    return func(*args, **kwargs)
  File "C:\Users\bhavya\Desktop\sad_final\sad_project\garbage_project\garbage_app\views.py", line 80, in Register_Garbage_User
    logging.debug(Garbage_User.objects.get(email_id=email))
  File "C:\Users\bhavya\Anaconda3\envs\myenv1\lib\site-packages\django\db\models\manager.py", line 82, in manager_method
    return getattr(self.get_queryset(), name)(*args, **kwargs)
  File "C:\Users\bhavya\Anaconda3\envs\myenv1\lib\site-packages\django\db\models\query.py", line 408, in get
    self.model._meta.object_name
garbage_app.models.Garbage_User.DoesNotExist: Garbage_User matching query does not exist.
2019-09-23 18:27:15,164 - DEBUG - somill@gmailaa.com
2019-09-23 18:27:15,190 - ERROR - Internal Server Error: /user/register/
Traceback (most recent call last):
  File "C:\Users\bhavya\Anaconda3\envs\myenv1\lib\site-packages\django\core\handlers\exception.py", line 34, in inner
    response = get_response(request)
  File "C:\Users\bhavya\Anaconda3\envs\myenv1\lib\site-packages\django\core\handlers\base.py", line 115, in _get_response
    response = self.process_exception_by_middleware(e, request)
  File "C:\Users\bhavya\Anaconda3\envs\myenv1\lib\site-packages\django\core\handlers\base.py", line 113, in _get_response
    response = wrapped_callback(request, *callback_args, **callback_kwargs)
  File "C:\Users\bhavya\Anaconda3\envs\myenv1\lib\site-packages\django\views\decorators\csrf.py", line 54, in wrapped_view
    return view_func(*args, **kwargs)
  File "C:\Users\bhavya\Anaconda3\envs\myenv1\lib\site-packages\django\views\generic\base.py", line 71, in view
    return self.dispatch(request, *args, **kwargs)
  File "C:\Users\bhavya\Anaconda3\envs\myenv1\lib\site-packages\rest_framework\views.py", line 497, in dispatch
    response = self.handle_exception(exc)
  File "C:\Users\bhavya\Anaconda3\envs\myenv1\lib\site-packages\rest_framework\views.py", line 457, in handle_exception
    self.raise_uncaught_exception(exc)
  File "C:\Users\bhavya\Anaconda3\envs\myenv1\lib\site-packages\rest_framework\views.py", line 468, in raise_uncaught_exception
    raise exc
  File "C:\Users\bhavya\Anaconda3\envs\myenv1\lib\site-packages\rest_framework\views.py", line 494, in dispatch
    response = handler(request, *args, **kwargs)
  File "C:\Users\bhavya\Anaconda3\envs\myenv1\lib\site-packages\rest_framework\decorators.py", line 50, in handler
    return func(*args, **kwargs)
  File "C:\Users\bhavya\Desktop\sad_final\sad_project\garbage_project\garbage_app\views.py", line 80, in Register_Garbage_User
    logging.debug(Garbage_User.objects.get(email_id=email))
  File "C:\Users\bhavya\Anaconda3\envs\myenv1\lib\site-packages\django\db\models\manager.py", line 82, in manager_method
    return getattr(self.get_queryset(), name)(*args, **kwargs)
  File "C:\Users\bhavya\Anaconda3\envs\myenv1\lib\site-packages\django\db\models\query.py", line 408, in get
    self.model._meta.object_name
garbage_app.models.Garbage_User.DoesNotExist: Garbage_User matching query does not exist.
2019-09-23 18:29:01,376 - INFO - C:\Users\bhavya\Desktop\sad_final\sad_project\garbage_project\garbage_app\views.py changed, reloading.
2019-09-23 18:29:45,482 - INFO - C:\Users\bhavya\Desktop\sad_final\sad_project\garbage_project\garbage_app\views.py changed, reloading.
2019-09-23 18:30:18,822 - INFO - C:\Users\bhavya\Desktop\sad_final\sad_project\garbage_project\garbage_app\views.py changed, reloading.
2019-09-23 18:31:25,209 - INFO - C:\Users\bhavya\Desktop\sad_final\sad_project\garbage_project\garbage_app\views.py changed, reloading.
2019-09-23 18:32:07,941 - INFO - C:\Users\bhavya\Desktop\sad_final\sad_project\garbage_project\garbage_app\views.py changed, reloading.
2019-09-23 18:33:47,421 - INFO - C:\Users\bhavya\Desktop\sad_final\sad_project\garbage_project\garbage_app\views.py changed, reloading.
2019-09-23 18:34:16,366 - INFO - C:\Users\bhavya\Desktop\sad_final\sad_project\garbage_project\garbage_app\views.py changed, reloading.
2019-09-23 18:38:48,523 - INFO - C:\Users\bhavya\Desktop\sad_final\sad_project\garbage_project\garbage_app\views.py changed, reloading.
2019-09-23 18:39:16,959 - INFO - C:\Users\bhavya\Desktop\sad_final\sad_project\garbage_project\garbage_app\views.py changed, reloading.
2019-09-23 18:40:09,880 - INFO - C:\Users\bhavya\Desktop\sad_final\sad_project\garbage_project\garbage_app\views.py changed, reloading.
2019-09-23 18:40:22,084 - INFO - C:\Users\bhavya\Desktop\sad_final\sad_project\garbage_project\garbage_app\views.py changed, reloading.
2019-09-23 18:41:05,409 - INFO - C:\Users\bhavya\Desktop\sad_final\sad_project\garbage_project\garbage_app\views.py changed, reloading.
2019-09-23 18:43:31,815 - INFO - C:\Users\bhavya\Desktop\sad_final\sad_project\garbage_project\garbage_app\views.py changed, reloading.
2019-09-23 18:48:05,556 - WARNING - Method Not Allowed: /user/login/
2019-09-23 18:54:41,106 - INFO - C:\Users\bhavya\Desktop\sad_final\sad_project\garbage_project\garbage_app\views.py changed, reloading.
2019-09-23 18:54:57,790 - INFO - C:\Users\bhavya\Desktop\sad_final\sad_project\garbage_project\garbage_app\views.py changed, reloading.
2019-09-23 18:58:48,059 - INFO - C:\Users\bhavya\Desktop\sad_final\sad_project\garbage_project\garbage_app\views.py changed, reloading.
2019-09-23 19:23:43,906 - INFO - C:\Users\bhavya\Desktop\sad_final\sad_project\garbage_project\garbage_app\views.py changed, reloading.
2019-09-23 19:23:50,498 - ERROR - Internal Server Error: /user/login/
Traceback (most recent call last):
  File "C:\Users\bhavya\Desktop\sad_final\sad_project\garbage_project\garbage_app\views.py", line 61, in validate_Garbage_User_view
    return HTTPResponse(dict)
NameError: name 'HTTPResponse' is not defined

During handling of the above exception, another exception occurred:

Traceback (most recent call last):
  File "C:\Users\bhavya\Anaconda3\envs\myenv1\lib\site-packages\django\core\handlers\exception.py", line 34, in inner
    response = get_response(request)
  File "C:\Users\bhavya\Anaconda3\envs\myenv1\lib\site-packages\django\core\handlers\base.py", line 115, in _get_response
    response = self.process_exception_by_middleware(e, request)
  File "C:\Users\bhavya\Anaconda3\envs\myenv1\lib\site-packages\django\core\handlers\base.py", line 113, in _get_response
    response = wrapped_callback(request, *callback_args, **callback_kwargs)
  File "C:\Users\bhavya\Anaconda3\envs\myenv1\lib\site-packages\django\views\decorators\csrf.py", line 54, in wrapped_view
    return view_func(*args, **kwargs)
  File "C:\Users\bhavya\Anaconda3\envs\myenv1\lib\site-packages\django\views\generic\base.py", line 71, in view
    return self.dispatch(request, *args, **kwargs)
  File "C:\Users\bhavya\Anaconda3\envs\myenv1\lib\site-packages\rest_framework\views.py", line 497, in dispatch
    response = self.handle_exception(exc)
  File "C:\Users\bhavya\Anaconda3\envs\myenv1\lib\site-packages\rest_framework\views.py", line 457, in handle_exception
    self.raise_uncaught_exception(exc)
  File "C:\Users\bhavya\Anaconda3\envs\myenv1\lib\site-packages\rest_framework\views.py", line 468, in raise_uncaught_exception
    raise exc
  File "C:\Users\bhavya\Anaconda3\envs\myenv1\lib\site-packages\rest_framework\views.py", line 494, in dispatch
    response = handler(request, *args, **kwargs)
  File "C:\Users\bhavya\Anaconda3\envs\myenv1\lib\site-packages\rest_framework\decorators.py", line 50, in handler
    return func(*args, **kwargs)
  File "C:\Users\bhavya\Desktop\sad_final\sad_project\garbage_project\garbage_app\views.py", line 72, in validate_Garbage_User_view
    return JSONResponse(dict)
NameError: name 'JSONResponse' is not defined
2019-09-23 19:24:15,017 - INFO - C:\Users\bhavya\Desktop\sad_final\sad_project\garbage_project\garbage_app\views.py changed, reloading.
2019-09-23 19:24:20,923 - ERROR - Internal Server Error: /user/login/
Traceback (most recent call last):
  File "C:\Users\bhavya\Desktop\sad_final\sad_project\garbage_project\garbage_app\views.py", line 61, in validate_Garbage_User_view
    return HTTPResponse(dict)
NameError: name 'HTTPResponse' is not defined

During handling of the above exception, another exception occurred:

Traceback (most recent call last):
  File "C:\Users\bhavya\Anaconda3\envs\myenv1\lib\site-packages\django\core\handlers\exception.py", line 34, in inner
    response = get_response(request)
  File "C:\Users\bhavya\Anaconda3\envs\myenv1\lib\site-packages\django\core\handlers\base.py", line 115, in _get_response
    response = self.process_exception_by_middleware(e, request)
  File "C:\Users\bhavya\Anaconda3\envs\myenv1\lib\site-packages\django\core\handlers\base.py", line 113, in _get_response
    response = wrapped_callback(request, *callback_args, **callback_kwargs)
  File "C:\Users\bhavya\Anaconda3\envs\myenv1\lib\site-packages\django\views\decorators\csrf.py", line 54, in wrapped_view
    return view_func(*args, **kwargs)
  File "C:\Users\bhavya\Anaconda3\envs\myenv1\lib\site-packages\django\views\generic\base.py", line 71, in view
    return self.dispatch(request, *args, **kwargs)
  File "C:\Users\bhavya\Anaconda3\envs\myenv1\lib\site-packages\rest_framework\views.py", line 497, in dispatch
    response = self.handle_exception(exc)
  File "C:\Users\bhavya\Anaconda3\envs\myenv1\lib\site-packages\rest_framework\views.py", line 457, in handle_exception
    self.raise_uncaught_exception(exc)
  File "C:\Users\bhavya\Anaconda3\envs\myenv1\lib\site-packages\rest_framework\views.py", line 468, in raise_uncaught_exception
    raise exc
  File "C:\Users\bhavya\Anaconda3\envs\myenv1\lib\site-packages\rest_framework\views.py", line 494, in dispatch
    response = handler(request, *args, **kwargs)
  File "C:\Users\bhavya\Anaconda3\envs\myenv1\lib\site-packages\rest_framework\decorators.py", line 50, in handler
    return func(*args, **kwargs)
  File "C:\Users\bhavya\Desktop\sad_final\sad_project\garbage_project\garbage_app\views.py", line 72, in validate_Garbage_User_view
    return HTTPResponse(dict)
NameError: name 'HTTPResponse' is not defined
2019-09-23 19:25:46,070 - INFO - C:\Users\bhavya\Desktop\sad_final\sad_project\garbage_project\garbage_app\views.py changed, reloading.
2019-09-23 19:25:59,778 - INFO - C:\Users\bhavya\Desktop\sad_final\sad_project\garbage_project\garbage_app\views.py changed, reloading.
2019-09-23 19:26:03,212 - ERROR - Internal Server Error: /user/login/
Traceback (most recent call last):
  File "C:\Users\bhavya\Desktop\sad_final\sad_project\garbage_project\garbage_app\views.py", line 61, in validate_Garbage_User_view
    return HTTpResponse(dict)
NameError: name 'HTTpResponse' is not defined

During handling of the above exception, another exception occurred:

Traceback (most recent call last):
  File "C:\Users\bhavya\Anaconda3\envs\myenv1\lib\site-packages\django\core\handlers\exception.py", line 34, in inner
    response = get_response(request)
  File "C:\Users\bhavya\Anaconda3\envs\myenv1\lib\site-packages\django\core\handlers\base.py", line 115, in _get_response
    response = self.process_exception_by_middleware(e, request)
  File "C:\Users\bhavya\Anaconda3\envs\myenv1\lib\site-packages\django\core\handlers\base.py", line 113, in _get_response
    response = wrapped_callback(request, *callback_args, **callback_kwargs)
  File "C:\Users\bhavya\Anaconda3\envs\myenv1\lib\site-packages\django\views\decorators\csrf.py", line 54, in wrapped_view
    return view_func(*args, **kwargs)
  File "C:\Users\bhavya\Anaconda3\envs\myenv1\lib\site-packages\django\views\generic\base.py", line 71, in view
    return self.dispatch(request, *args, **kwargs)
  File "C:\Users\bhavya\Anaconda3\envs\myenv1\lib\site-packages\rest_framework\views.py", line 497, in dispatch
    response = self.handle_exception(exc)
  File "C:\Users\bhavya\Anaconda3\envs\myenv1\lib\site-packages\rest_framework\views.py", line 457, in handle_exception
    self.raise_uncaught_exception(exc)
  File "C:\Users\bhavya\Anaconda3\envs\myenv1\lib\site-packages\rest_framework\views.py", line 468, in raise_uncaught_exception
    raise exc
  File "C:\Users\bhavya\Anaconda3\envs\myenv1\lib\site-packages\rest_framework\views.py", line 494, in dispatch
    response = handler(request, *args, **kwargs)
  File "C:\Users\bhavya\Anaconda3\envs\myenv1\lib\site-packages\rest_framework\decorators.py", line 50, in handler
    return func(*args, **kwargs)
  File "C:\Users\bhavya\Desktop\sad_final\sad_project\garbage_project\garbage_app\views.py", line 72, in validate_Garbage_User_view
    return HTTpResponse(dict)
NameError: name 'HTTpResponse' is not defined
2019-09-23 19:26:32,079 - INFO - C:\Users\bhavya\Desktop\sad_final\sad_project\garbage_project\garbage_app\views.py changed, reloading.
2019-09-23 19:26:36,195 - ERROR - Internal Server Error: /user/login/
Traceback (most recent call last):
  File "C:\Users\bhavya\Desktop\sad_final\sad_project\garbage_project\garbage_app\views.py", line 61, in validate_Garbage_User_view
    return HttpResponse(dict)
NameError: name 'HttpResponse' is not defined

During handling of the above exception, another exception occurred:

Traceback (most recent call last):
  File "C:\Users\bhavya\Anaconda3\envs\myenv1\lib\site-packages\django\core\handlers\exception.py", line 34, in inner
    response = get_response(request)
  File "C:\Users\bhavya\Anaconda3\envs\myenv1\lib\site-packages\django\core\handlers\base.py", line 115, in _get_response
    response = self.process_exception_by_middleware(e, request)
  File "C:\Users\bhavya\Anaconda3\envs\myenv1\lib\site-packages\django\core\handlers\base.py", line 113, in _get_response
    response = wrapped_callback(request, *callback_args, **callback_kwargs)
  File "C:\Users\bhavya\Anaconda3\envs\myenv1\lib\site-packages\django\views\decorators\csrf.py", line 54, in wrapped_view
    return view_func(*args, **kwargs)
  File "C:\Users\bhavya\Anaconda3\envs\myenv1\lib\site-packages\django\views\generic\base.py", line 71, in view
    return self.dispatch(request, *args, **kwargs)
  File "C:\Users\bhavya\Anaconda3\envs\myenv1\lib\site-packages\rest_framework\views.py", line 497, in dispatch
    response = self.handle_exception(exc)
  File "C:\Users\bhavya\Anaconda3\envs\myenv1\lib\site-packages\rest_framework\views.py", line 457, in handle_exception
    self.raise_uncaught_exception(exc)
  File "C:\Users\bhavya\Anaconda3\envs\myenv1\lib\site-packages\rest_framework\views.py", line 468, in raise_uncaught_exception
    raise exc
  File "C:\Users\bhavya\Anaconda3\envs\myenv1\lib\site-packages\rest_framework\views.py", line 494, in dispatch
    response = handler(request, *args, **kwargs)
  File "C:\Users\bhavya\Anaconda3\envs\myenv1\lib\site-packages\rest_framework\decorators.py", line 50, in handler
    return func(*args, **kwargs)
  File "C:\Users\bhavya\Desktop\sad_final\sad_project\garbage_project\garbage_app\views.py", line 72, in validate_Garbage_User_view
    return HttpResponse(dict)
NameError: name 'HttpResponse' is not defined
2019-09-23 19:27:30,025 - INFO - C:\Users\bhavya\Desktop\sad_final\sad_project\garbage_project\garbage_app\views.py changed, reloading.
2019-09-23 19:28:34,691 - INFO - C:\Users\bhavya\Desktop\sad_final\sad_project\garbage_project\garbage_app\views.py changed, reloading.
2019-09-23 19:28:38,256 - INFO - C:\Users\bhavya\Desktop\sad_final\sad_project\garbage_project\garbage_app\views.py changed, reloading.
2019-09-23 19:40:24,012 - INFO - C:\Users\bhavya\Desktop\sad_final\sad_project\garbage_project\garbage_app\views.py changed, reloading.
2019-09-23 19:41:50,127 - INFO - C:\Users\bhavya\Desktop\sad_final\sad_project\garbage_project\garbage_app\views.py changed, reloading.
2019-09-23 19:45:05,683 - WARNING - Not Found: /user/lregister/
2019-09-23 19:46:30,707 - INFO - C:\Users\bhavya\Desktop\sad_final\sad_project\garbage_project\garbage_app\views.py changed, reloading.
2019-09-23 19:46:56,362 - INFO - C:\Users\bhavya\Desktop\sad_final\sad_project\garbage_project\garbage_app\views.py changed, reloading.
2019-09-23 19:47:16,158 - INFO - C:\Users\bhavya\Desktop\sad_final\sad_project\garbage_project\garbage_app\views.py changed, reloading.
2019-09-23 19:47:49,190 - INFO - C:\Users\bhavya\Desktop\sad_final\sad_project\garbage_project\garbage_app\views.py changed, reloading.
2019-09-23 19:48:06,801 - INFO - C:\Users\bhavya\Desktop\sad_final\sad_project\garbage_project\garbage_app\views.py changed, reloading.
2019-09-23 19:48:28,012 - INFO - C:\Users\bhavya\Desktop\sad_final\sad_project\garbage_project\garbage_app\views.py changed, reloading.
2019-09-23 20:20:47,156 - ERROR - Internal Server Error: /postAPI
Traceback (most recent call last):
  File "C:\Users\bhavya\Anaconda3\envs\myenv1\lib\site-packages\django\core\handlers\exception.py", line 34, in inner
    response = get_response(request)
  File "C:\Users\bhavya\Anaconda3\envs\myenv1\lib\site-packages\django\utils\deprecation.py", line 93, in __call__
    response = self.process_request(request)
  File "C:\Users\bhavya\Anaconda3\envs\myenv1\lib\site-packages\django\middleware\common.py", line 53, in process_request
    path = self.get_full_path_with_slash(request)
  File "C:\Users\bhavya\Anaconda3\envs\myenv1\lib\site-packages\django\middleware\common.py", line 93, in get_full_path_with_slash
    'url': request.get_host() + new_path,
RuntimeError: You called this URL via POST, but the URL doesn't end in a slash and you have APPEND_SLASH set. Django can't redirect to the slash URL while maintaining POST data. Change your form to point to 127.0.0.1:8000/postAPI/ (note the trailing slash), or set APPEND_SLASH=False in your Django settings.
2019-09-23 20:59:02,982 - INFO - C:\Users\bhavya\Desktop\sad_final\sad_project\garbage_project\garbage_app\views.py changed, reloading.
