2019-09-22 22:29:39,694 - INFO - C:\Users\bhavya\Desktop\sad_final\sad_project\garbage_project\garbage_app\views.py changed, reloading.
2019-09-22 22:29:41,050 - DEBUG - Hello world 
2019-09-22 22:30:24,534 - INFO - C:\Users\bhavya\Desktop\sad_final\sad_project\garbage_project\garbage_app\views.py changed, reloading.
2019-09-22 22:44:17,593 - INFO - C:\Users\bhavya\Desktop\sad_final\sad_project\garbage_project\garbage_app\views.py changed, reloading.
2019-09-22 22:44:34,371 - INFO - C:\Users\bhavya\Desktop\sad_final\sad_project\garbage_project\garbage_app\views.py changed, reloading.
2019-09-22 22:45:51,705 - INFO - C:\Users\bhavya\Desktop\sad_final\sad_project\garbage_project\garbage_app\views.py changed, reloading.
2019-09-22 22:46:09,915 - ERROR - Internal Server Error: /user/register/
Traceback (most recent call last):
  File "C:\Users\bhavya\Anaconda3\envs\myenv1\lib\site-packages\django\core\handlers\exception.py", line 34, in inner
    response = get_response(request)
  File "C:\Users\bhavya\Anaconda3\envs\myenv1\lib\site-packages\django\core\handlers\base.py", line 115, in _get_response
    response = self.process_exception_by_middleware(e, request)
  File "C:\Users\bhavya\Anaconda3\envs\myenv1\lib\site-packages\django\core\handlers\base.py", line 113, in _get_response
    response = wrapped_callback(request, *callback_args, **callback_kwargs)
  File "C:\Users\bhavya\Anaconda3\envs\myenv1\lib\site-packages\django\views\decorators\csrf.py", line 54, in wrapped_view
    return view_func(*args, **kwargs)
  File "C:\Users\bhavya\Anaconda3\envs\myenv1\lib\site-packages\django\views\generic\base.py", line 71, in view
    return self.dispatch(request, *args, **kwargs)
  File "C:\Users\bhavya\Anaconda3\envs\myenv1\lib\site-packages\rest_framework\views.py", line 497, in dispatch
    response = self.handle_exception(exc)
  File "C:\Users\bhavya\Anaconda3\envs\myenv1\lib\site-packages\rest_framework\views.py", line 457, in handle_exception
    self.raise_uncaught_exception(exc)
  File "C:\Users\bhavya\Anaconda3\envs\myenv1\lib\site-packages\rest_framework\views.py", line 468, in raise_uncaught_exception
    raise exc
  File "C:\Users\bhavya\Anaconda3\envs\myenv1\lib\site-packages\rest_framework\views.py", line 494, in dispatch
    response = handler(request, *args, **kwargs)
  File "C:\Users\bhavya\Anaconda3\envs\myenv1\lib\site-packages\rest_framework\decorators.py", line 50, in handler
    return func(*args, **kwargs)
  File "C:\Users\bhavya\Desktop\sad_final\sad_project\garbage_project\garbage_app\views.py", line 77, in Register_Garbage_User
    email=request.data[0]["email_id"]
KeyError: 0
2019-09-22 22:48:06,594 - ERROR - Internal Server Error: /user/register/
Traceback (most recent call last):
  File "C:\Users\bhavya\Anaconda3\envs\myenv1\lib\site-packages\django\core\handlers\exception.py", line 34, in inner
    response = get_response(request)
  File "C:\Users\bhavya\Anaconda3\envs\myenv1\lib\site-packages\django\core\handlers\base.py", line 115, in _get_response
    response = self.process_exception_by_middleware(e, request)
  File "C:\Users\bhavya\Anaconda3\envs\myenv1\lib\site-packages\django\core\handlers\base.py", line 113, in _get_response
    response = wrapped_callback(request, *callback_args, **callback_kwargs)
  File "C:\Users\bhavya\Anaconda3\envs\myenv1\lib\site-packages\django\views\decorators\csrf.py", line 54, in wrapped_view
    return view_func(*args, **kwargs)
  File "C:\Users\bhavya\Anaconda3\envs\myenv1\lib\site-packages\django\views\generic\base.py", line 71, in view
    return self.dispatch(request, *args, **kwargs)
  File "C:\Users\bhavya\Anaconda3\envs\myenv1\lib\site-packages\rest_framework\views.py", line 497, in dispatch
    response = self.handle_exception(exc)
  File "C:\Users\bhavya\Anaconda3\envs\myenv1\lib\site-packages\rest_framework\views.py", line 457, in handle_exception
    self.raise_uncaught_exception(exc)
  File "C:\Users\bhavya\Anaconda3\envs\myenv1\lib\site-packages\rest_framework\views.py", line 468, in raise_uncaught_exception
    raise exc
  File "C:\Users\bhavya\Anaconda3\envs\myenv1\lib\site-packages\rest_framework\views.py", line 494, in dispatch
    response = handler(request, *args, **kwargs)
  File "C:\Users\bhavya\Anaconda3\envs\myenv1\lib\site-packages\rest_framework\decorators.py", line 50, in handler
    return func(*args, **kwargs)
  File "C:\Users\bhavya\Desktop\sad_final\sad_project\garbage_project\garbage_app\views.py", line 77, in Register_Garbage_User
    email=request.data[0]["email_id"]
KeyError: 0
2019-09-22 22:50:32,632 - INFO - C:\Users\bhavya\Desktop\sad_final\sad_project\garbage_project\garbage_app\views.py changed, reloading.
2019-09-22 22:50:35,729 - ERROR - Internal Server Error: /user/register/
Traceback (most recent call last):
  File "C:\Users\bhavya\Anaconda3\envs\myenv1\lib\site-packages\django\core\handlers\exception.py", line 34, in inner
    response = get_response(request)
  File "C:\Users\bhavya\Anaconda3\envs\myenv1\lib\site-packages\django\core\handlers\base.py", line 115, in _get_response
    response = self.process_exception_by_middleware(e, request)
  File "C:\Users\bhavya\Anaconda3\envs\myenv1\lib\site-packages\django\core\handlers\base.py", line 113, in _get_response
    response = wrapped_callback(request, *callback_args, **callback_kwargs)
  File "C:\Users\bhavya\Anaconda3\envs\myenv1\lib\site-packages\django\views\decorators\csrf.py", line 54, in wrapped_view
    return view_func(*args, **kwargs)
  File "C:\Users\bhavya\Anaconda3\envs\myenv1\lib\site-packages\django\views\generic\base.py", line 71, in view
    return self.dispatch(request, *args, **kwargs)
  File "C:\Users\bhavya\Anaconda3\envs\myenv1\lib\site-packages\rest_framework\views.py", line 497, in dispatch
    response = self.handle_exception(exc)
  File "C:\Users\bhavya\Anaconda3\envs\myenv1\lib\site-packages\rest_framework\views.py", line 457, in handle_exception
    self.raise_uncaught_exception(exc)
  File "C:\Users\bhavya\Anaconda3\envs\myenv1\lib\site-packages\rest_framework\views.py", line 468, in raise_uncaught_exception
    raise exc
  File "C:\Users\bhavya\Anaconda3\envs\myenv1\lib\site-packages\rest_framework\views.py", line 494, in dispatch
    response = handler(request, *args, **kwargs)
  File "C:\Users\bhavya\Anaconda3\envs\myenv1\lib\site-packages\rest_framework\decorators.py", line 50, in handler
    return func(*args, **kwargs)
  File "C:\Users\bhavya\Desktop\sad_final\sad_project\garbage_project\garbage_app\views.py", line 77, in Register_Garbage_User
    email=request.data[0]["email_id"]
KeyError: 0
2019-09-22 22:55:34,210 - DEBUG - aman@gmailaa.com
2019-09-22 22:55:34,217 - DEBUG - Garbage_User object (3)
2019-09-22 23:06:45,741 - INFO - C:\Users\bhavya\Desktop\sad_final\sad_project\garbage_project\garbage_app\models.py changed, reloading.
2019-09-22 23:14:36,643 - INFO - C:\Users\bhavya\Desktop\sad_final\sad_project\garbage_project\garbage_app\views.py changed, reloading.
2019-09-23 17:23:54,407 - INFO - C:\Users\bhavya\Desktop\sad_final\sad_project\garbage_project\garbage_project\urls.py changed, reloading.
2019-09-23 17:26:53,326 - INFO - C:\Users\bhavya\Desktop\sad_final\sad_project\garbage_project\garbage_project\urls.py changed, reloading.
2019-09-23 17:27:04,719 - INFO - C:\Users\bhavya\Desktop\sad_final\sad_project\garbage_project\garbage_app\views.py changed, reloading.
2019-09-23 17:29:34,090 - WARNING - Bad Request: /postAPI/
2019-09-23 18:10:10,022 - INFO - C:\Users\bhavya\Desktop\sad_final\sad_project\garbage_project\garbage_app\views.py changed, reloading.
2019-09-23 18:11:01,232 - INFO - C:\Users\bhavya\Desktop\sad_final\sad_project\garbage_project\garbage_app\views.py changed, reloading.
2019-09-23 18:11:09,961 - INFO - C:\Users\bhavya\Desktop\sad_final\sad_project\garbage_project\garbage_app\views.py changed, reloading.
2019-09-23 18:12:45,224 - ERROR - Internal Server Error: /user/register
Traceback (most recent call last):
  File "C:\Users\bhavya\Anaconda3\envs\myenv1\lib\site-packages\django\core\handlers\exception.py", line 34, in inner
    response = get_response(request)
  File "C:\Users\bhavya\Anaconda3\envs\myenv1\lib\site-packages\django\utils\deprecation.py", line 93, in __call__
    response = self.process_request(request)
  File "C:\Users\bhavya\Anaconda3\envs\myenv1\lib\site-packages\django\middleware\common.py", line 53, in process_request
    path = self.get_full_path_with_slash(request)
  File "C:\Users\bhavya\Anaconda3\envs\myenv1\lib\site-packages\django\middleware\common.py", line 93, in get_full_path_with_slash
    'url': request.get_host() + new_path,
RuntimeError: You called this URL via POST, but the URL doesn't end in a slash and you have APPEND_SLASH set. Django can't redirect to the slash URL while maintaining POST data. Change your form to point to 127.0.0.1:8000/user/register/ (note the trailing slash), or set APPEND_SLASH=False in your Django settings.
2019-09-23 18:13:36,969 - DEBUG - somi@gmailaa.com
2019-09-23 18:13:37,051 - ERROR - Internal Server Error: /user/register/
Traceback (most recent call last):
  File "C:\Users\bhavya\Anaconda3\envs\myenv1\lib\site-packages\django\core\handlers\exception.py", line 34, in inner
    response = get_response(request)
  File "C:\Users\bhavya\Anaconda3\envs\myenv1\lib\site-packages\django\core\handlers\base.py", line 115, in _get_response
    response = self.process_exception_by_middleware(e, request)
  File "C:\Users\bhavya\Anaconda3\envs\myenv1\lib\site-packages\django\core\handlers\base.py", line 113, in _get_response
    response = wrapped_callback(request, *callback_args, **callback_kwargs)
  File "C:\Users\bhavya\Anaconda3\envs\myenv1\lib\site-packages\django\views\decorators\csrf.py", line 54, in wrapped_view
    return view_func(*args, **kwargs)
  File "C:\Users\bhavya\Anaconda3\envs\myenv1\lib\site-packages\django\views\generic\base.py", line 71, in view
    return self.dispatch(request, *args, **kwargs)
  File "C:\Users\bhavya\Anaconda3\envs\myenv1\lib\site-packages\rest_framework\views.py", line 497, in dispatch
    response = self.handle_exception(exc)
  File "C:\Users\bhavya\Anaconda3\envs\myenv1\lib\site-packages\rest_framework\views.py", line 457, in handle_exception
    self.raise_uncaught_exception(exc)
  File "C:\Users\bhavya\Anaconda3\envs\myenv1\lib\site-packages\rest_framework\views.py", line 468, in raise_uncaught_exception
    raise exc
  File "C:\Users\bhavya\Anaconda3\envs\myenv1\lib\site-packages\rest_framework\views.py", line 494, in dispatch
    response = handler(request, *args, **kwargs)
  File "C:\Users\bhavya\Anaconda3\envs\myenv1\lib\site-packages\rest_framework\decorators.py", line 50, in handler
    return func(*args, **kwargs)
  File "C:\Users\bhavya\Desktop\sad_final\sad_project\garbage_project\garbage_app\views.py", line 80, in Register_Garbage_User
    logging.debug(Garbage_User.objects.get(email_id=email))
  File "C:\Users\bhavya\Anaconda3\envs\myenv1\lib\site-packages\django\db\models\manager.py", line 82, in manager_method
    return getattr(self.get_queryset(), name)(*args, **kwargs)
  File "C:\Users\bhavya\Anaconda3\envs\myenv1\lib\site-packages\django\db\models\query.py", line 408, in get
    self.model._meta.object_name
garbage_app.models.Garbage_User.DoesNotExist: Garbage_User matching query does not exist.
2019-09-23 18:15:38,153 - DEBUG - somi@gmailaa.com
2019-09-23 18:15:38,170 - ERROR - Internal Server Error: /user/register/
Traceback (most recent call last):
  File "C:\Users\bhavya\Anaconda3\envs\myenv1\lib\site-packages\django\core\handlers\exception.py", line 34, in inner
    response = get_response(request)
  File "C:\Users\bhavya\Anaconda3\envs\myenv1\lib\site-packages\django\core\handlers\base.py", line 115, in _get_response
    response = self.process_exception_by_middleware(e, request)
  File "C:\Users\bhavya\Anaconda3\envs\myenv1\lib\site-packages\django\core\handlers\base.py", line 113, in _get_response
    response = wrapped_callback(request, *callback_args, **callback_kwargs)
  File "C:\Users\bhavya\Anaconda3\envs\myenv1\lib\site-packages\django\views\decorators\csrf.py", line 54, in wrapped_view
    return view_func(*args, **kwargs)
  File "C:\Users\bhavya\Anaconda3\envs\myenv1\lib\site-packages\django\views\generic\base.py", line 71, in view
    return self.dispatch(request, *args, **kwargs)
  File "C:\Users\bhavya\Anaconda3\envs\myenv1\lib\site-packages\rest_framework\views.py", line 497, in dispatch
    response = self.handle_exception(exc)
  File "C:\Users\bhavya\Anaconda3\envs\myenv1\lib\site-packages\rest_framework\views.py", line 457, in handle_exception
    self.raise_uncaught_exception(exc)
  File "C:\Users\bhavya\Anaconda3\envs\myenv1\lib\site-packages\rest_framework\views.py", line 468, in raise_uncaught_exception
    raise exc
  File "C:\Users\bhavya\Anaconda3\envs\myenv1\lib\site-packages\rest_framework\views.py", line 494, in dispatch
    response = handler(request, *args, **kwargs)
  File "C:\Users\bhavya\Anaconda3\envs\myenv1\lib\site-packages\rest_framework\decorators.py", line 50, in handler
    return func(*args, **kwargs)
  File "C:\Users\bhavya\Desktop\sad_final\sad_project\garbage_project\garbage_app\views.py", line 80, in Register_Garbage_User
    logging.debug(Garbage_User.objects.get(email_id=email))
  File "C:\Users\bhavya\Anaconda3\envs\myenv1\lib\site-packages\django\db\models\manager.py", line 82, in manager_method
    return getattr(self.get_queryset(), name)(*args, **kwargs)
  File "C:\Users\bhavya\Anaconda3\envs\myenv1\lib\site-packages\django\db\models\query.py", line 408, in get
    self.model._meta.object_name
garbage_app.models.Garbage_User.DoesNotExist: Garbage_User matching query does not exist.
2019-09-23 18:16:50,819 - INFO - C:\Users\bhavya\Desktop\sad_final\sad_project\garbage_project\garbage_app\views.py changed, reloading.
2019-09-23 18:17:20,658 - DEBUG - somi@gmailaa.com
2019-09-23 18:17:20,681 - ERROR - Internal Server Error: /user/register/
Traceback (most recent call last):
  File "C:\Users\bhavya\Anaconda3\envs\myenv1\lib\site-packages\django\core\handlers\exception.py", line 34, in inner
    response = get_response(request)
  File "C:\Users\bhavya\Anaconda3\envs\myenv1\lib\site-packages\django\core\handlers\base.py", line 115, in _get_response
    response = self.process_exception_by_middleware(e, request)
  File "C:\Users\bhavya\Anaconda3\envs\myenv1\lib\site-packages\django\core\handlers\base.py", line 113, in _get_response
    response = wrapped_callback(request, *callback_args, **callback_kwargs)
  File "C:\Users\bhavya\Anaconda3\envs\myenv1\lib\site-packages\django\views\decorators\csrf.py", line 54, in wrapped_view
    return view_func(*args, **kwargs)
  File "C:\Users\bhavya\Anaconda3\envs\myenv1\lib\site-packages\django\views\generic\base.py", line 71, in view
    return self.dispatch(request, *args, **kwargs)
  File "C:\Users\bhavya\Anaconda3\envs\myenv1\lib\site-packages\rest_framework\views.py", line 497, in dispatch
    response = self.handle_exception(exc)
  File "C:\Users\bhavya\Anaconda3\envs\myenv1\lib\site-packages\rest_framework\views.py", line 457, in handle_exception
    self.raise_uncaught_exception(exc)
  File "C:\Users\bhavya\Anaconda3\envs\myenv1\lib\site-packages\rest_framework\views.py", line 468, in raise_uncaught_exception
    raise exc
  File "C:\Users\bhavya\Anaconda3\envs\myenv1\lib\site-packages\rest_framework\views.py", line 494, in dispatch
    response = handler(request, *args, **kwargs)
  File "C:\Users\bhavya\Anaconda3\envs\myenv1\lib\site-packages\rest_framework\decorators.py", line 50, in handler
    return func(*args, **kwargs)
  File "C:\Users\bhavya\Desktop\sad_final\sad_project\garbage_project\garbage_app\views.py", line 80, in Register_Garbage_User
    logging.debug(Garbage_User.objects.get(email_id=email))
  File "C:\Users\bhavya\Anaconda3\envs\myenv1\lib\site-packages\django\db\models\manager.py", line 82, in manager_method
    return getattr(self.get_queryset(), name)(*args, **kwargs)
  File "C:\Users\bhavya\Anaconda3\envs\myenv1\lib\site-packages\django\db\models\query.py", line 408, in get
    self.model._meta.object_name
garbage_app.models.Garbage_User.DoesNotExist: Garbage_User matching query does not exist.
2019-09-23 18:17:44,084 - INFO - C:\Users\bhavya\Desktop\sad_final\sad_project\garbage_project\garbage_app\views.py changed, reloading.
2019-09-23 18:18:25,282 - WARNING - Method Not Allowed: /user/register/
2019-09-23 18:18:51,822 - DEBUG - somi@gmailaa.com
2019-09-23 18:18:51,860 - ERROR - Internal Server Error: /user/register/
Traceback (most recent call last):
  File "C:\Users\bhavya\Anaconda3\envs\myenv1\lib\site-packages\django\core\handlers\exception.py", line 34, in inner
    response = get_response(request)
  File "C:\Users\bhavya\Anaconda3\envs\myenv1\lib\site-packages\django\core\handlers\base.py", line 115, in _get_response
    response = self.process_exception_by_middleware(e, request)
  File "C:\Users\bhavya\Anaconda3\envs\myenv1\lib\site-packages\django\core\handlers\base.py", line 113, in _get_response
    response = wrapped_callback(request, *callback_args, **callback_kwargs)
  File "C:\Users\bhavya\Anaconda3\envs\myenv1\lib\site-packages\django\views\decorators\csrf.py", line 54, in wrapped_view
    return view_func(*args, **kwargs)
  File "C:\Users\bhavya\Anaconda3\envs\myenv1\lib\site-packages\django\views\generic\base.py", line 71, in view
    return self.dispatch(request, *args, **kwargs)
  File "C:\Users\bhavya\Anaconda3\envs\myenv1\lib\site-packages\rest_framework\views.py", line 497, in dispatch
    response = self.handle_exception(exc)
  File "C:\Users\bhavya\Anaconda3\envs\myenv1\lib\site-packages\rest_framework\views.py", line 457, in handle_exception
    self.raise_uncaught_exception(exc)
  File "C:\Users\bhavya\Anaconda3\envs\myenv1\lib\site-packages\rest_framework\views.py", line 468, in raise_uncaught_exception
    raise exc
  File "C:\Users\bhavya\Anaconda3\envs\myenv1\lib\site-packages\rest_framework\views.py", line 494, in dispatch
    response = handler(request, *args, **kwargs)
  File "C:\Users\bhavya\Anaconda3\envs\myenv1\lib\site-packages\rest_framework\decorators.py", line 50, in handler
    return func(*args, **kwargs)
  File "C:\Users\bhavya\Desktop\sad_final\sad_project\garbage_project\garbage_app\views.py", line 80, in Register_Garbage_User
    logging.debug(Garbage_User.objects.get(email_id=email))
  File "C:\Users\bhavya\Anaconda3\envs\myenv1\lib\site-packages\django\db\models\manager.py", line 82, in manager_method
    return getattr(self.get_queryset(), name)(*args, **kwargs)
  File "C:\Users\bhavya\Anaconda3\envs\myenv1\lib\site-packages\django\db\models\query.py", line 408, in get
    self.model._meta.object_name
garbage_app.models.Garbage_User.DoesNotExist: Garbage_User matching query does not exist.
2019-09-23 18:24:59,110 - INFO - C:\Users\bhavya\Desktop\sad_final\sad_project\garbage_project\garbage_app\views.py changed, reloading.
2019-09-23 18:25:59,992 - DEBUG - somi@gmailaa.com
2019-09-23 18:26:00,024 - ERROR - Internal Server Error: /user/register/
Traceback (most recent call last):
  File "C:\Users\bhavya\Anaconda3\envs\myenv1\lib\site-packages\django\core\handlers\exception.py", line 34, in inner
    response = get_response(request)
  File "C:\Users\bhavya\Anaconda3\envs\myenv1\lib\site-packages\django\core\handlers\base.py", line 115, in _get_response
    response = self.process_exception_by_middleware(e, request)
  File "C:\Users\bhavya\Anaconda3\envs\myenv1\lib\site-packages\django\core\handlers\base.py", line 113, in _get_response
    response = wrapped_callback(request, *callback_args, **callback_kwargs)
  File "C:\Users\bhavya\Anaconda3\envs\myenv1\lib\site-packages\django\views\decorators\csrf.py", line 54, in wrapped_view
    return view_func(*args, **kwargs)
  File "C:\Users\bhavya\Anaconda3\envs\myenv1\lib\site-packages\django\views\generic\base.py", line 71, in view
    return self.dispatch(request, *args, **kwargs)
  File "C:\Users\bhavya\Anaconda3\envs\myenv1\lib\site-packages\rest_framework\views.py", line 497, in dispatch
    response = self.handle_exception(exc)
  File "C:\Users\bhavya\Anaconda3\envs\myenv1\lib\site-packages\rest_framework\views.py", line 457, in handle_exception
    self.raise_uncaught_exception(exc)
  File "C:\Users\bhavya\Anaconda3\envs\myenv1\lib\site-packages\rest_framework\views.py", line 468, in raise_uncaught_exception
    raise exc
  File "C:\Users\bhavya\Anaconda3\envs\myenv1\lib\site-packages\rest_framework\views.py", line 494, in dispatch
    response = handler(request, *args, **kwargs)
  File "C:\Users\bhavya\Anaconda3\envs\myenv1\lib\site-packages\rest_framework\decorators.py", line 50, in handler
    return func(*args, **kwargs)
  File "C:\Users\bhavya\Desktop\sad_final\sad_project\garbage_project\garbage_app\views.py", line 80, in Register_Garbage_User
    logging.debug(Garbage_User.objects.get(email_id=email))
  File "C:\Users\bhavya\Anaconda3\envs\myenv1\lib\site-packages\django\db\models\manager.py", line 82, in manager_method
    return getattr(self.get_queryset(), name)(*args, **kwargs)
  File "C:\Users\bhavya\Anaconda3\envs\myenv1\lib\site-packages\django\db\models\query.py", line 408, in get
    self.model._meta.object_name
garbage_app.models.Garbage_User.DoesNotExist: Garbage_User matching query does not exist.
2019-09-23 18:27:15,164 - DEBUG - somill@gmailaa.com
2019-09-23 18:27:15,190 - ERROR - Internal Server Error: /user/register/
Traceback (most recent call last):
  File "C:\Users\bhavya\Anaconda3\envs\myenv1\lib\site-packages\django\core\handlers\exception.py", line 34, in inner
    response = get_response(request)
  File "C:\Users\bhavya\Anaconda3\envs\myenv1\lib\site-packages\django\core\handlers\base.py", line 115, in _get_response
    response = self.process_exception_by_middleware(e, request)
  File "C:\Users\bhavya\Anaconda3\envs\myenv1\lib\site-packages\django\core\handlers\base.py", line 113, in _get_response
    response = wrapped_callback(request, *callback_args, **callback_kwargs)
  File "C:\Users\bhavya\Anaconda3\envs\myenv1\lib\site-packages\django\views\decorators\csrf.py", line 54, in wrapped_view
    return view_func(*args, **kwargs)
  File "C:\Users\bhavya\Anaconda3\envs\myenv1\lib\site-packages\django\views\generic\base.py", line 71, in view
    return self.dispatch(request, *args, **kwargs)
  File "C:\Users\bhavya\Anaconda3\envs\myenv1\lib\site-packages\rest_framework\views.py", line 497, in dispatch
    response = self.handle_exception(exc)
  File "C:\Users\bhavya\Anaconda3\envs\myenv1\lib\site-packages\rest_framework\views.py", line 457, in handle_exception
    self.raise_uncaught_exception(exc)
  File "C:\Users\bhavya\Anaconda3\envs\myenv1\lib\site-packages\rest_framework\views.py", line 468, in raise_uncaught_exception
    raise exc
  File "C:\Users\bhavya\Anaconda3\envs\myenv1\lib\site-packages\rest_framework\views.py", line 494, in dispatch
    response = handler(request, *args, **kwargs)
  File "C:\Users\bhavya\Anaconda3\envs\myenv1\lib\site-packages\rest_framework\decorators.py", line 50, in handler
    return func(*args, **kwargs)
  File "C:\Users\bhavya\Desktop\sad_final\sad_project\garbage_project\garbage_app\views.py", line 80, in Register_Garbage_User
    logging.debug(Garbage_User.objects.get(email_id=email))
  File "C:\Users\bhavya\Anaconda3\envs\myenv1\lib\site-packages\django\db\models\manager.py", line 82, in manager_method
    return getattr(self.get_queryset(), name)(*args, **kwargs)
  File "C:\Users\bhavya\Anaconda3\envs\myenv1\lib\site-packages\django\db\models\query.py", line 408, in get
    self.model._meta.object_name
garbage_app.models.Garbage_User.DoesNotExist: Garbage_User matching query does not exist.
2019-09-23 18:29:01,376 - INFO - C:\Users\bhavya\Desktop\sad_final\sad_project\garbage_project\garbage_app\views.py changed, reloading.
2019-09-23 18:29:45,482 - INFO - C:\Users\bhavya\Desktop\sad_final\sad_project\garbage_project\garbage_app\views.py changed, reloading.
2019-09-23 18:30:18,822 - INFO - C:\Users\bhavya\Desktop\sad_final\sad_project\garbage_project\garbage_app\views.py changed, reloading.
2019-09-23 18:31:25,209 - INFO - C:\Users\bhavya\Desktop\sad_final\sad_project\garbage_project\garbage_app\views.py changed, reloading.
2019-09-23 18:32:07,941 - INFO - C:\Users\bhavya\Desktop\sad_final\sad_project\garbage_project\garbage_app\views.py changed, reloading.
2019-09-23 18:33:47,421 - INFO - C:\Users\bhavya\Desktop\sad_final\sad_project\garbage_project\garbage_app\views.py changed, reloading.
2019-09-23 18:34:16,366 - INFO - C:\Users\bhavya\Desktop\sad_final\sad_project\garbage_project\garbage_app\views.py changed, reloading.
2019-09-23 18:38:48,523 - INFO - C:\Users\bhavya\Desktop\sad_final\sad_project\garbage_project\garbage_app\views.py changed, reloading.
2019-09-23 18:39:16,959 - INFO - C:\Users\bhavya\Desktop\sad_final\sad_project\garbage_project\garbage_app\views.py changed, reloading.
2019-09-23 18:40:09,880 - INFO - C:\Users\bhavya\Desktop\sad_final\sad_project\garbage_project\garbage_app\views.py changed, reloading.
2019-09-23 18:40:22,084 - INFO - C:\Users\bhavya\Desktop\sad_final\sad_project\garbage_project\garbage_app\views.py changed, reloading.
2019-09-23 18:41:05,409 - INFO - C:\Users\bhavya\Desktop\sad_final\sad_project\garbage_project\garbage_app\views.py changed, reloading.
2019-09-23 18:43:31,815 - INFO - C:\Users\bhavya\Desktop\sad_final\sad_project\garbage_project\garbage_app\views.py changed, reloading.
2019-09-23 18:48:05,556 - WARNING - Method Not Allowed: /user/login/
2019-09-23 18:54:41,106 - INFO - C:\Users\bhavya\Desktop\sad_final\sad_project\garbage_project\garbage_app\views.py changed, reloading.
2019-09-23 18:54:57,790 - INFO - C:\Users\bhavya\Desktop\sad_final\sad_project\garbage_project\garbage_app\views.py changed, reloading.
2019-09-23 18:58:48,059 - INFO - C:\Users\bhavya\Desktop\sad_final\sad_project\garbage_project\garbage_app\views.py changed, reloading.
2019-09-23 19:23:43,906 - INFO - C:\Users\bhavya\Desktop\sad_final\sad_project\garbage_project\garbage_app\views.py changed, reloading.
2019-09-23 19:23:50,498 - ERROR - Internal Server Error: /user/login/
Traceback (most recent call last):
  File "C:\Users\bhavya\Desktop\sad_final\sad_project\garbage_project\garbage_app\views.py", line 61, in validate_Garbage_User_view
    return HTTPResponse(dict)
NameError: name 'HTTPResponse' is not defined

During handling of the above exception, another exception occurred:

Traceback (most recent call last):
  File "C:\Users\bhavya\Anaconda3\envs\myenv1\lib\site-packages\django\core\handlers\exception.py", line 34, in inner
    response = get_response(request)
  File "C:\Users\bhavya\Anaconda3\envs\myenv1\lib\site-packages\django\core\handlers\base.py", line 115, in _get_response
    response = self.process_exception_by_middleware(e, request)
  File "C:\Users\bhavya\Anaconda3\envs\myenv1\lib\site-packages\django\core\handlers\base.py", line 113, in _get_response
    response = wrapped_callback(request, *callback_args, **callback_kwargs)
  File "C:\Users\bhavya\Anaconda3\envs\myenv1\lib\site-packages\django\views\decorators\csrf.py", line 54, in wrapped_view
    return view_func(*args, **kwargs)
  File "C:\Users\bhavya\Anaconda3\envs\myenv1\lib\site-packages\django\views\generic\base.py", line 71, in view
    return self.dispatch(request, *args, **kwargs)
  File "C:\Users\bhavya\Anaconda3\envs\myenv1\lib\site-packages\rest_framework\views.py", line 497, in dispatch
    response = self.handle_exception(exc)
  File "C:\Users\bhavya\Anaconda3\envs\myenv1\lib\site-packages\rest_framework\views.py", line 457, in handle_exception
    self.raise_uncaught_exception(exc)
  File "C:\Users\bhavya\Anaconda3\envs\myenv1\lib\site-packages\rest_framework\views.py", line 468, in raise_uncaught_exception
    raise exc
  File "C:\Users\bhavya\Anaconda3\envs\myenv1\lib\site-packages\rest_framework\views.py", line 494, in dispatch
    response = handler(request, *args, **kwargs)
  File "C:\Users\bhavya\Anaconda3\envs\myenv1\lib\site-packages\rest_framework\decorators.py", line 50, in handler
    return func(*args, **kwargs)
  File "C:\Users\bhavya\Desktop\sad_final\sad_project\garbage_project\garbage_app\views.py", line 72, in validate_Garbage_User_view
    return JSONResponse(dict)
NameError: name 'JSONResponse' is not defined
2019-09-23 19:24:15,017 - INFO - C:\Users\bhavya\Desktop\sad_final\sad_project\garbage_project\garbage_app\views.py changed, reloading.
2019-09-23 19:24:20,923 - ERROR - Internal Server Error: /user/login/
Traceback (most recent call last):
  File "C:\Users\bhavya\Desktop\sad_final\sad_project\garbage_project\garbage_app\views.py", line 61, in validate_Garbage_User_view
    return HTTPResponse(dict)
NameError: name 'HTTPResponse' is not defined

During handling of the above exception, another exception occurred:

Traceback (most recent call last):
  File "C:\Users\bhavya\Anaconda3\envs\myenv1\lib\site-packages\django\core\handlers\exception.py", line 34, in inner
    response = get_response(request)
  File "C:\Users\bhavya\Anaconda3\envs\myenv1\lib\site-packages\django\core\handlers\base.py", line 115, in _get_response
    response = self.process_exception_by_middleware(e, request)
  File "C:\Users\bhavya\Anaconda3\envs\myenv1\lib\site-packages\django\core\handlers\base.py", line 113, in _get_response
    response = wrapped_callback(request, *callback_args, **callback_kwargs)
  File "C:\Users\bhavya\Anaconda3\envs\myenv1\lib\site-packages\django\views\decorators\csrf.py", line 54, in wrapped_view
    return view_func(*args, **kwargs)
  File "C:\Users\bhavya\Anaconda3\envs\myenv1\lib\site-packages\django\views\generic\base.py", line 71, in view
    return self.dispatch(request, *args, **kwargs)
  File "C:\Users\bhavya\Anaconda3\envs\myenv1\lib\site-packages\rest_framework\views.py", line 497, in dispatch
    response = self.handle_exception(exc)
  File "C:\Users\bhavya\Anaconda3\envs\myenv1\lib\site-packages\rest_framework\views.py", line 457, in handle_exception
    self.raise_uncaught_exception(exc)
  File "C:\Users\bhavya\Anaconda3\envs\myenv1\lib\site-packages\rest_framework\views.py", line 468, in raise_uncaught_exception
    raise exc
  File "C:\Users\bhavya\Anaconda3\envs\myenv1\lib\site-packages\rest_framework\views.py", line 494, in dispatch
    response = handler(request, *args, **kwargs)
  File "C:\Users\bhavya\Anaconda3\envs\myenv1\lib\site-packages\rest_framework\decorators.py", line 50, in handler
    return func(*args, **kwargs)
  File "C:\Users\bhavya\Desktop\sad_final\sad_project\garbage_project\garbage_app\views.py", line 72, in validate_Garbage_User_view
    return HTTPResponse(dict)
NameError: name 'HTTPResponse' is not defined
2019-09-23 19:25:46,070 - INFO - C:\Users\bhavya\Desktop\sad_final\sad_project\garbage_project\garbage_app\views.py changed, reloading.
2019-09-23 19:25:59,778 - INFO - C:\Users\bhavya\Desktop\sad_final\sad_project\garbage_project\garbage_app\views.py changed, reloading.
2019-09-23 19:26:03,212 - ERROR - Internal Server Error: /user/login/
Traceback (most recent call last):
  File "C:\Users\bhavya\Desktop\sad_final\sad_project\garbage_project\garbage_app\views.py", line 61, in validate_Garbage_User_view
    return HTTpResponse(dict)
NameError: name 'HTTpResponse' is not defined

During handling of the above exception, another exception occurred:

Traceback (most recent call last):
  File "C:\Users\bhavya\Anaconda3\envs\myenv1\lib\site-packages\django\core\handlers\exception.py", line 34, in inner
    response = get_response(request)
  File "C:\Users\bhavya\Anaconda3\envs\myenv1\lib\site-packages\django\core\handlers\base.py", line 115, in _get_response
    response = self.process_exception_by_middleware(e, request)
  File "C:\Users\bhavya\Anaconda3\envs\myenv1\lib\site-packages\django\core\handlers\base.py", line 113, in _get_response
    response = wrapped_callback(request, *callback_args, **callback_kwargs)
  File "C:\Users\bhavya\Anaconda3\envs\myenv1\lib\site-packages\django\views\decorators\csrf.py", line 54, in wrapped_view
    return view_func(*args, **kwargs)
  File "C:\Users\bhavya\Anaconda3\envs\myenv1\lib\site-packages\django\views\generic\base.py", line 71, in view
    return self.dispatch(request, *args, **kwargs)
  File "C:\Users\bhavya\Anaconda3\envs\myenv1\lib\site-packages\rest_framework\views.py", line 497, in dispatch
    response = self.handle_exception(exc)
  File "C:\Users\bhavya\Anaconda3\envs\myenv1\lib\site-packages\rest_framework\views.py", line 457, in handle_exception
    self.raise_uncaught_exception(exc)
  File "C:\Users\bhavya\Anaconda3\envs\myenv1\lib\site-packages\rest_framework\views.py", line 468, in raise_uncaught_exception
    raise exc
  File "C:\Users\bhavya\Anaconda3\envs\myenv1\lib\site-packages\rest_framework\views.py", line 494, in dispatch
    response = handler(request, *args, **kwargs)
  File "C:\Users\bhavya\Anaconda3\envs\myenv1\lib\site-packages\rest_framework\decorators.py", line 50, in handler
    return func(*args, **kwargs)
  File "C:\Users\bhavya\Desktop\sad_final\sad_project\garbage_project\garbage_app\views.py", line 72, in validate_Garbage_User_view
    return HTTpResponse(dict)
NameError: name 'HTTpResponse' is not defined
2019-09-23 19:26:32,079 - INFO - C:\Users\bhavya\Desktop\sad_final\sad_project\garbage_project\garbage_app\views.py changed, reloading.
2019-09-23 19:26:36,195 - ERROR - Internal Server Error: /user/login/
Traceback (most recent call last):
  File "C:\Users\bhavya\Desktop\sad_final\sad_project\garbage_project\garbage_app\views.py", line 61, in validate_Garbage_User_view
    return HttpResponse(dict)
NameError: name 'HttpResponse' is not defined

During handling of the above exception, another exception occurred:

Traceback (most recent call last):
  File "C:\Users\bhavya\Anaconda3\envs\myenv1\lib\site-packages\django\core\handlers\exception.py", line 34, in inner
    response = get_response(request)
  File "C:\Users\bhavya\Anaconda3\envs\myenv1\lib\site-packages\django\core\handlers\base.py", line 115, in _get_response
    response = self.process_exception_by_middleware(e, request)
  File "C:\Users\bhavya\Anaconda3\envs\myenv1\lib\site-packages\django\core\handlers\base.py", line 113, in _get_response
    response = wrapped_callback(request, *callback_args, **callback_kwargs)
  File "C:\Users\bhavya\Anaconda3\envs\myenv1\lib\site-packages\django\views\decorators\csrf.py", line 54, in wrapped_view
    return view_func(*args, **kwargs)
  File "C:\Users\bhavya\Anaconda3\envs\myenv1\lib\site-packages\django\views\generic\base.py", line 71, in view
    return self.dispatch(request, *args, **kwargs)
  File "C:\Users\bhavya\Anaconda3\envs\myenv1\lib\site-packages\rest_framework\views.py", line 497, in dispatch
    response = self.handle_exception(exc)
  File "C:\Users\bhavya\Anaconda3\envs\myenv1\lib\site-packages\rest_framework\views.py", line 457, in handle_exception
    self.raise_uncaught_exception(exc)
  File "C:\Users\bhavya\Anaconda3\envs\myenv1\lib\site-packages\rest_framework\views.py", line 468, in raise_uncaught_exception
    raise exc
  File "C:\Users\bhavya\Anaconda3\envs\myenv1\lib\site-packages\rest_framework\views.py", line 494, in dispatch
    response = handler(request, *args, **kwargs)
  File "C:\Users\bhavya\Anaconda3\envs\myenv1\lib\site-packages\rest_framework\decorators.py", line 50, in handler
    return func(*args, **kwargs)
  File "C:\Users\bhavya\Desktop\sad_final\sad_project\garbage_project\garbage_app\views.py", line 72, in validate_Garbage_User_view
    return HttpResponse(dict)
NameError: name 'HttpResponse' is not defined
2019-09-23 19:27:30,025 - INFO - C:\Users\bhavya\Desktop\sad_final\sad_project\garbage_project\garbage_app\views.py changed, reloading.
2019-09-23 19:28:34,691 - INFO - C:\Users\bhavya\Desktop\sad_final\sad_project\garbage_project\garbage_app\views.py changed, reloading.
2019-09-23 19:28:38,256 - INFO - C:\Users\bhavya\Desktop\sad_final\sad_project\garbage_project\garbage_app\views.py changed, reloading.
2019-09-23 19:40:24,012 - INFO - C:\Users\bhavya\Desktop\sad_final\sad_project\garbage_project\garbage_app\views.py changed, reloading.
2019-09-23 19:41:50,127 - INFO - C:\Users\bhavya\Desktop\sad_final\sad_project\garbage_project\garbage_app\views.py changed, reloading.
2019-09-23 19:45:05,683 - WARNING - Not Found: /user/lregister/
2019-09-23 19:46:30,707 - INFO - C:\Users\bhavya\Desktop\sad_final\sad_project\garbage_project\garbage_app\views.py changed, reloading.
2019-09-23 19:46:56,362 - INFO - C:\Users\bhavya\Desktop\sad_final\sad_project\garbage_project\garbage_app\views.py changed, reloading.
2019-09-23 19:47:16,158 - INFO - C:\Users\bhavya\Desktop\sad_final\sad_project\garbage_project\garbage_app\views.py changed, reloading.
2019-09-23 19:47:49,190 - INFO - C:\Users\bhavya\Desktop\sad_final\sad_project\garbage_project\garbage_app\views.py changed, reloading.
2019-09-23 19:48:06,801 - INFO - C:\Users\bhavya\Desktop\sad_final\sad_project\garbage_project\garbage_app\views.py changed, reloading.
2019-09-23 19:48:28,012 - INFO - C:\Users\bhavya\Desktop\sad_final\sad_project\garbage_project\garbage_app\views.py changed, reloading.
2019-09-23 20:20:47,156 - ERROR - Internal Server Error: /postAPI
Traceback (most recent call last):
  File "C:\Users\bhavya\Anaconda3\envs\myenv1\lib\site-packages\django\core\handlers\exception.py", line 34, in inner
    response = get_response(request)
  File "C:\Users\bhavya\Anaconda3\envs\myenv1\lib\site-packages\django\utils\deprecation.py", line 93, in __call__
    response = self.process_request(request)
  File "C:\Users\bhavya\Anaconda3\envs\myenv1\lib\site-packages\django\middleware\common.py", line 53, in process_request
    path = self.get_full_path_with_slash(request)
  File "C:\Users\bhavya\Anaconda3\envs\myenv1\lib\site-packages\django\middleware\common.py", line 93, in get_full_path_with_slash
    'url': request.get_host() + new_path,
RuntimeError: You called this URL via POST, but the URL doesn't end in a slash and you have APPEND_SLASH set. Django can't redirect to the slash URL while maintaining POST data. Change your form to point to 127.0.0.1:8000/postAPI/ (note the trailing slash), or set APPEND_SLASH=False in your Django settings.
2019-09-23 20:59:02,982 - INFO - C:\Users\bhavya\Desktop\sad_final\sad_project\garbage_project\garbage_app\views.py changed, reloading.
2019-09-23 21:10:38,038 - INFO - C:\Users\bhavya\Desktop\sad_final\sad_project\garbage_project\garbage_app\views.py changed, reloading.
2019-09-23 21:23:46,331 - INFO - C:\Users\bhavya\Desktop\sad_final\sad_project\garbage_project\garbage_app\models.py changed, reloading.
2019-09-23 21:27:49,909 - INFO - C:\Users\bhavya\Desktop\sad_final\sad_project\garbage_project\garbage_app\views.py changed, reloading.
2019-09-23 21:33:17,291 - INFO - C:\Users\bhavya\Desktop\sad_final\sad_project\garbage_project\garbage_app\views.py changed, reloading.
2019-09-23 21:34:32,650 - INFO - C:\Users\bhavya\Desktop\sad_final\sad_project\garbage_project\garbage_app\views.py changed, reloading.
2019-09-23 22:01:33,708 - INFO - C:\Users\bhavya\Desktop\sad_final\sad_project\garbage_project\garbage_app\views.py changed, reloading.
2019-09-23 22:02:19,591 - INFO - C:\Users\bhavya\Desktop\sad_final\sad_project\garbage_project\garbage_app\views.py changed, reloading.
2019-09-23 22:02:37,385 - INFO - C:\Users\bhavya\Desktop\sad_final\sad_project\garbage_project\garbage_app\views.py changed, reloading.
2019-09-23 22:02:55,099 - INFO - C:\Users\bhavya\Desktop\sad_final\sad_project\garbage_project\garbage_app\views.py changed, reloading.
2019-09-23 22:04:19,848 - INFO - C:\Users\bhavya\Desktop\sad_final\sad_project\garbage_project\garbage_project\urls.py changed, reloading.
2019-09-23 22:04:57,802 - INFO - C:\Users\bhavya\Desktop\sad_final\sad_project\garbage_project\garbage_project\urls.py changed, reloading.
2019-09-23 22:05:40,520 - ERROR - Internal Server Error: /postAPIModified
Traceback (most recent call last):
  File "C:\Users\bhavya\Anaconda3\envs\myenv1\lib\site-packages\django\core\handlers\exception.py", line 34, in inner
    response = get_response(request)
  File "C:\Users\bhavya\Anaconda3\envs\myenv1\lib\site-packages\django\utils\deprecation.py", line 93, in __call__
    response = self.process_request(request)
  File "C:\Users\bhavya\Anaconda3\envs\myenv1\lib\site-packages\django\middleware\common.py", line 53, in process_request
    path = self.get_full_path_with_slash(request)
  File "C:\Users\bhavya\Anaconda3\envs\myenv1\lib\site-packages\django\middleware\common.py", line 93, in get_full_path_with_slash
    'url': request.get_host() + new_path,
RuntimeError: You called this URL via POST, but the URL doesn't end in a slash and you have APPEND_SLASH set. Django can't redirect to the slash URL while maintaining POST data. Change your form to point to 127.0.0.1:8000/postAPIModified/ (note the trailing slash), or set APPEND_SLASH=False in your Django settings.
2019-09-23 22:06:26,380 - WARNING - Unsupported Media Type: /postAPIModified/
2019-09-23 22:07:09,647 - WARNING - Unsupported Media Type: /postAPIModified/
2019-09-23 22:07:18,258 - WARNING - Unsupported Media Type: /postAPIModified/
2019-09-23 22:10:05,073 - INFO - C:\Users\bhavya\Desktop\sad_final\sad_project\garbage_project\garbage_project\urls.py changed, reloading.
2019-09-23 22:12:02,763 - WARNING - Unsupported Media Type: /postAPIModified/
2019-09-23 22:25:58,166 - INFO - C:\Users\bhavya\Desktop\sad_final\sad_project\garbage_project\garbage_app\views.py changed, reloading.
2019-09-23 22:26:52,298 - INFO - C:\Users\bhavya\Desktop\sad_final\sad_project\garbage_project\garbage_app\views.py changed, reloading.
2019-09-23 22:27:18,628 - WARNING - Unsupported Media Type: /postAPIModified/
2019-09-23 22:30:41,052 - INFO - C:\Users\bhavya\Desktop\sad_final\sad_project\garbage_project\garbage_app\views.py changed, reloading.
2019-09-23 22:31:41,554 - INFO - C:\Users\bhavya\Desktop\sad_final\sad_project\garbage_project\garbage_app\views.py changed, reloading.
2019-09-23 22:33:21,137 - INFO - C:\Users\bhavya\Desktop\sad_final\sad_project\garbage_project\garbage_app\views.py changed, reloading.
2019-09-23 22:40:00,007 - INFO - C:\Users\bhavya\Desktop\sad_final\sad_project\garbage_project\garbage_app\serializers.py changed, reloading.
2019-09-23 22:41:17,299 - INFO - C:\Users\bhavya\Desktop\sad_final\sad_project\garbage_project\garbage_app\views.py changed, reloading.
2019-09-23 22:44:04,143 - INFO - C:\Users\bhavya\Desktop\sad_final\sad_project\garbage_project\garbage_app\views.py changed, reloading.
2019-09-23 22:44:46,049 - WARNING - Not Found: /postAPII/
2019-09-23 22:46:07,338 - INFO - C:\Users\bhavya\Desktop\sad_final\sad_project\garbage_project\garbage_app\views.py changed, reloading.
2019-09-23 22:48:39,219 - WARNING - Method Not Allowed: /postAPIModified/
2019-09-23 22:49:00,960 - ERROR - Internal Server Error: /postAPIModified/
Traceback (most recent call last):
  File "C:\Users\bhavya\Anaconda3\envs\myenv1\lib\site-packages\django\core\handlers\exception.py", line 34, in inner
    response = get_response(request)
  File "C:\Users\bhavya\Anaconda3\envs\myenv1\lib\site-packages\django\core\handlers\base.py", line 115, in _get_response
    response = self.process_exception_by_middleware(e, request)
  File "C:\Users\bhavya\Anaconda3\envs\myenv1\lib\site-packages\django\core\handlers\base.py", line 113, in _get_response
    response = wrapped_callback(request, *callback_args, **callback_kwargs)
  File "C:\Users\bhavya\Anaconda3\envs\myenv1\lib\site-packages\django\views\decorators\csrf.py", line 54, in wrapped_view
    return view_func(*args, **kwargs)
  File "C:\Users\bhavya\Anaconda3\envs\myenv1\lib\site-packages\django\views\generic\base.py", line 71, in view
    return self.dispatch(request, *args, **kwargs)
  File "C:\Users\bhavya\Anaconda3\envs\myenv1\lib\site-packages\rest_framework\views.py", line 497, in dispatch
    response = self.handle_exception(exc)
  File "C:\Users\bhavya\Anaconda3\envs\myenv1\lib\site-packages\rest_framework\views.py", line 457, in handle_exception
    self.raise_uncaught_exception(exc)
  File "C:\Users\bhavya\Anaconda3\envs\myenv1\lib\site-packages\rest_framework\views.py", line 468, in raise_uncaught_exception
    raise exc
  File "C:\Users\bhavya\Anaconda3\envs\myenv1\lib\site-packages\rest_framework\views.py", line 494, in dispatch
    response = handler(request, *args, **kwargs)
  File "C:\Users\bhavya\Anaconda3\envs\myenv1\lib\site-packages\rest_framework\decorators.py", line 50, in handler
    return func(*args, **kwargs)
  File "C:\Users\bhavya\Desktop\sad_final\sad_project\garbage_project\garbage_app\views.py", line 127, in send_post
    "image": null,
NameError: name 'null' is not defined
2019-09-23 22:49:52,631 - INFO - C:\Users\bhavya\Desktop\sad_final\sad_project\garbage_project\garbage_app\views.py changed, reloading.
2019-09-23 22:50:38,237 - WARNING - Method Not Allowed: /postAPIModified/
2019-09-23 22:51:39,331 - WARNING - Method Not Allowed: /postAPIModified/
2019-09-23 22:53:36,652 - INFO - C:\Users\bhavya\Desktop\sad_final\sad_project\garbage_project\garbage_app\views.py changed, reloading.
2019-09-23 22:55:50,317 - INFO - C:\Users\bhavya\Desktop\sad_final\sad_project\garbage_project\garbage_app\views.py changed, reloading.
2019-09-23 22:59:09,881 - INFO - C:\Users\bhavya\Desktop\sad_final\sad_project\garbage_project\garbage_app\views.py changed, reloading.
2019-09-23 23:00:35,215 - INFO - C:\Users\bhavya\Desktop\sad_final\sad_project\garbage_project\garbage_app\views.py changed, reloading.
2019-09-23 23:01:17,775 - WARNING - Not Found: /postAPI/
2019-09-23 23:01:27,893 - WARNING - Method Not Allowed: /postAPIModified/
2019-09-23 23:01:52,903 - INFO - C:\Users\bhavya\Desktop\sad_final\sad_project\garbage_project\garbage_project\urls.py changed, reloading.
2019-09-23 23:01:56,577 - INFO - C:\Users\bhavya\Desktop\sad_final\sad_project\garbage_project\garbage_project\urls.py changed, reloading.
2019-09-23 23:02:27,435 - INFO - C:\Users\bhavya\Desktop\sad_final\sad_project\garbage_project\garbage_app\views.py changed, reloading.
2019-09-23 23:03:07,608 - INFO - C:\Users\bhavya\Desktop\sad_final\sad_project\garbage_project\garbage_app\views.py changed, reloading.
2019-09-23 23:04:35,879 - INFO - C:\Users\bhavya\Desktop\sad_final\sad_project\garbage_project\garbage_app\views.py changed, reloading.
2019-09-23 23:05:14,791 - INFO - C:\Users\bhavya\Desktop\sad_final\sad_project\garbage_project\garbage_app\views.py changed, reloading.
2019-09-23 23:06:03,517 - INFO - C:\Users\bhavya\Desktop\sad_final\sad_project\garbage_project\garbage_app\views.py changed, reloading.
2019-09-23 23:08:13,754 - INFO - C:\Users\bhavya\Desktop\sad_final\sad_project\garbage_project\garbage_app\views.py changed, reloading.
2019-09-23 23:10:39,247 - INFO - C:\Users\bhavya\Desktop\sad_final\sad_project\garbage_project\garbage_app\views.py changed, reloading.
2019-09-23 23:10:50,292 - INFO - C:\Users\bhavya\Desktop\sad_final\sad_project\garbage_project\garbage_app\views.py changed, reloading.
2019-09-23 23:11:40,192 - INFO - C:\Users\bhavya\Desktop\sad_final\sad_project\garbage_project\garbage_app\views.py changed, reloading.
2019-09-23 23:12:48,335 - WARNING - Method Not Allowed: /postAPIModified/
2019-09-23 23:22:55,021 - INFO - C:\Users\bhavya\Desktop\sad_final\sad_project\garbage_project\garbage_app\views.py changed, reloading.
2019-09-23 23:24:58,354 - INFO - C:\Users\bhavya\Desktop\sad_final\sad_project\garbage_project\garbage_app\views.py changed, reloading.
2019-09-23 23:33:00,619 - INFO - C:\Users\bhavya\Desktop\sad_final\sad_project\garbage_project\garbage_app\views.py changed, reloading.
2019-09-23 23:33:13,818 - ERROR - Internal Server Error: /postAPIModified/
Traceback (most recent call last):
  File "C:\Users\bhavya\Anaconda3\envs\myenv1\lib\site-packages\django\core\handlers\exception.py", line 34, in inner
    response = get_response(request)
  File "C:\Users\bhavya\Anaconda3\envs\myenv1\lib\site-packages\django\core\handlers\base.py", line 145, in _get_response
    response = self.process_exception_by_middleware(e, request)
  File "C:\Users\bhavya\Anaconda3\envs\myenv1\lib\site-packages\django\core\handlers\base.py", line 143, in _get_response
    response = response.render()
  File "C:\Users\bhavya\Anaconda3\envs\myenv1\lib\site-packages\django\template\response.py", line 106, in render
    self.content = self.rendered_content
  File "C:\Users\bhavya\Anaconda3\envs\myenv1\lib\site-packages\rest_framework\response.py", line 70, in rendered_content
    ret = renderer.render(self.data, accepted_media_type, context)
  File "C:\Users\bhavya\Anaconda3\envs\myenv1\lib\site-packages\rest_framework\renderers.py", line 104, in render
    allow_nan=not self.strict, separators=separators
  File "C:\Users\bhavya\Anaconda3\envs\myenv1\lib\site-packages\rest_framework\utils\json.py", line 25, in dumps
    return json.dumps(*args, **kwargs)
  File "C:\Users\bhavya\Anaconda3\envs\myenv1\lib\json\__init__.py", line 238, in dumps
    **kw).encode(obj)
  File "C:\Users\bhavya\Anaconda3\envs\myenv1\lib\json\encoder.py", line 199, in encode
    chunks = self.iterencode(o, _one_shot=True)
  File "C:\Users\bhavya\Anaconda3\envs\myenv1\lib\json\encoder.py", line 257, in iterencode
    return _iterencode(o, 0)
  File "C:\Users\bhavya\Anaconda3\envs\myenv1\lib\site-packages\rest_framework\utils\encoders.py", line 50, in default
    return obj.decode()
UnicodeDecodeError: 'utf-8' codec can't decode byte 0xff in position 0: invalid start byte
2019-09-23 23:35:49,384 - WARNING - Method Not Allowed: /postAPIModified/
2019-09-23 23:36:49,779 - WARNING - Method Not Allowed: /postAPIModified/
2019-09-23 23:39:52,499 - INFO - C:\Users\bhavya\Desktop\sad_final\sad_project\garbage_project\garbage_app\views.py changed, reloading.
2019-09-23 23:40:15,508 - ERROR - Internal Server Error: /postAPIModified/
Traceback (most recent call last):
  File "C:\Users\bhavya\Anaconda3\envs\myenv1\lib\site-packages\django\core\handlers\exception.py", line 34, in inner
    response = get_response(request)
  File "C:\Users\bhavya\Anaconda3\envs\myenv1\lib\site-packages\django\core\handlers\base.py", line 145, in _get_response
    response = self.process_exception_by_middleware(e, request)
  File "C:\Users\bhavya\Anaconda3\envs\myenv1\lib\site-packages\django\core\handlers\base.py", line 143, in _get_response
    response = response.render()
  File "C:\Users\bhavya\Anaconda3\envs\myenv1\lib\site-packages\django\template\response.py", line 106, in render
    self.content = self.rendered_content
  File "C:\Users\bhavya\Anaconda3\envs\myenv1\lib\site-packages\rest_framework\response.py", line 70, in rendered_content
    ret = renderer.render(self.data, accepted_media_type, context)
  File "C:\Users\bhavya\Anaconda3\envs\myenv1\lib\site-packages\rest_framework\renderers.py", line 104, in render
    allow_nan=not self.strict, separators=separators
  File "C:\Users\bhavya\Anaconda3\envs\myenv1\lib\site-packages\rest_framework\utils\json.py", line 25, in dumps
    return json.dumps(*args, **kwargs)
  File "C:\Users\bhavya\Anaconda3\envs\myenv1\lib\json\__init__.py", line 238, in dumps
    **kw).encode(obj)
  File "C:\Users\bhavya\Anaconda3\envs\myenv1\lib\json\encoder.py", line 199, in encode
    chunks = self.iterencode(o, _one_shot=True)
  File "C:\Users\bhavya\Anaconda3\envs\myenv1\lib\json\encoder.py", line 257, in iterencode
    return _iterencode(o, 0)
  File "C:\Users\bhavya\Anaconda3\envs\myenv1\lib\site-packages\rest_framework\utils\encoders.py", line 50, in default
    return obj.decode()
UnicodeDecodeError: 'utf-8' codec can't decode byte 0xff in position 0: invalid start byte
2019-09-23 23:41:21,939 - ERROR - Internal Server Error: /postAPIModified/
Traceback (most recent call last):
  File "C:\Users\bhavya\Anaconda3\envs\myenv1\lib\site-packages\django\core\handlers\exception.py", line 34, in inner
    response = get_response(request)
  File "C:\Users\bhavya\Anaconda3\envs\myenv1\lib\site-packages\django\core\handlers\base.py", line 145, in _get_response
    response = self.process_exception_by_middleware(e, request)
  File "C:\Users\bhavya\Anaconda3\envs\myenv1\lib\site-packages\django\core\handlers\base.py", line 143, in _get_response
    response = response.render()
  File "C:\Users\bhavya\Anaconda3\envs\myenv1\lib\site-packages\django\template\response.py", line 106, in render
    self.content = self.rendered_content
  File "C:\Users\bhavya\Anaconda3\envs\myenv1\lib\site-packages\rest_framework\response.py", line 70, in rendered_content
    ret = renderer.render(self.data, accepted_media_type, context)
  File "C:\Users\bhavya\Anaconda3\envs\myenv1\lib\site-packages\rest_framework\renderers.py", line 104, in render
    allow_nan=not self.strict, separators=separators
  File "C:\Users\bhavya\Anaconda3\envs\myenv1\lib\site-packages\rest_framework\utils\json.py", line 25, in dumps
    return json.dumps(*args, **kwargs)
  File "C:\Users\bhavya\Anaconda3\envs\myenv1\lib\json\__init__.py", line 238, in dumps
    **kw).encode(obj)
  File "C:\Users\bhavya\Anaconda3\envs\myenv1\lib\json\encoder.py", line 199, in encode
    chunks = self.iterencode(o, _one_shot=True)
  File "C:\Users\bhavya\Anaconda3\envs\myenv1\lib\json\encoder.py", line 257, in iterencode
    return _iterencode(o, 0)
  File "C:\Users\bhavya\Anaconda3\envs\myenv1\lib\site-packages\rest_framework\utils\encoders.py", line 50, in default
    return obj.decode()
UnicodeDecodeError: 'utf-8' codec can't decode byte 0xff in position 0: invalid start byte
2019-09-23 23:42:08,364 - INFO - C:\Users\bhavya\Desktop\sad_final\sad_project\garbage_project\garbage_app\views.py changed, reloading.
2019-09-23 23:43:29,259 - INFO - C:\Users\bhavya\Desktop\sad_final\sad_project\garbage_project\garbage_project\urls.py changed, reloading.
2019-09-24 16:10:20,133 - INFO - C:\Users\Harsh\Desktop\sad_project\garbage_project\garbage_app\models.py changed, reloading.
2019-09-24 16:31:31,447 - WARNING - Not Found: /favicon.ico
2019-09-24 16:35:02,780 - ERROR - Internal Server Error: /upvotelist/
Traceback (most recent call last):
  File "C:\Users\Harsh\Anaconda3\envs\myenv\lib\site-packages\django\core\handlers\exception.py", line 34, in inner
    response = get_response(request)
  File "C:\Users\Harsh\Anaconda3\envs\myenv\lib\site-packages\django\core\handlers\base.py", line 145, in _get_response
    response = self.process_exception_by_middleware(e, request)
  File "C:\Users\Harsh\Anaconda3\envs\myenv\lib\site-packages\django\core\handlers\base.py", line 143, in _get_response
    response = response.render()
  File "C:\Users\Harsh\Anaconda3\envs\myenv\lib\site-packages\django\template\response.py", line 106, in render
    self.content = self.rendered_content
  File "C:\Users\Harsh\Anaconda3\envs\myenv\lib\site-packages\rest_framework\response.py", line 70, in rendered_content
    ret = renderer.render(self.data, accepted_media_type, context)
  File "C:\Users\Harsh\Anaconda3\envs\myenv\lib\site-packages\rest_framework\renderers.py", line 725, in render
    context = self.get_context(data, accepted_media_type, renderer_context)
  File "C:\Users\Harsh\Anaconda3\envs\myenv\lib\site-packages\rest_framework\renderers.py", line 681, in get_context
    'content': self.get_content(renderer, data, accepted_media_type, renderer_context),
  File "C:\Users\Harsh\Anaconda3\envs\myenv\lib\site-packages\rest_framework\renderers.py", line 414, in get_content
    content = renderer.render(data, accepted_media_type, renderer_context)
  File "C:\Users\Harsh\Anaconda3\envs\myenv\lib\site-packages\rest_framework\renderers.py", line 104, in render
    allow_nan=not self.strict, separators=separators
  File "C:\Users\Harsh\Anaconda3\envs\myenv\lib\site-packages\rest_framework\utils\json.py", line 25, in dumps
    return json.dumps(*args, **kwargs)
  File "C:\Users\Harsh\Anaconda3\envs\myenv\lib\json\__init__.py", line 238, in dumps
    **kw).encode(obj)
  File "C:\Users\Harsh\Anaconda3\envs\myenv\lib\json\encoder.py", line 201, in encode
    chunks = list(chunks)
  File "C:\Users\Harsh\Anaconda3\envs\myenv\lib\json\encoder.py", line 439, in _iterencode
    yield from _iterencode(o, _current_indent_level)
  File "C:\Users\Harsh\Anaconda3\envs\myenv\lib\json\encoder.py", line 429, in _iterencode
    yield from _iterencode_list(o, _current_indent_level)
  File "C:\Users\Harsh\Anaconda3\envs\myenv\lib\json\encoder.py", line 325, in _iterencode_list
    yield from chunks
  File "C:\Users\Harsh\Anaconda3\envs\myenv\lib\json\encoder.py", line 438, in _iterencode
    o = _default(o)
  File "C:\Users\Harsh\Anaconda3\envs\myenv\lib\site-packages\rest_framework\utils\encoders.py", line 67, in default
    return super().default(obj)
  File "C:\Users\Harsh\Anaconda3\envs\myenv\lib\json\encoder.py", line 179, in default
    raise TypeError(f'Object of type {o.__class__.__name__} '
TypeError: Object of type Vote_table is not JSON serializable
2019-09-27 12:00:59,348 - ERROR - Internal Server Error: /upvotelist/
Traceback (most recent call last):
  File "C:\Users\Harsh\Anaconda3\envs\myenv\lib\site-packages\django\core\handlers\exception.py", line 34, in inner
    response = get_response(request)
  File "C:\Users\Harsh\Anaconda3\envs\myenv\lib\site-packages\django\core\handlers\base.py", line 145, in _get_response
    response = self.process_exception_by_middleware(e, request)
  File "C:\Users\Harsh\Anaconda3\envs\myenv\lib\site-packages\django\core\handlers\base.py", line 143, in _get_response
    response = response.render()
  File "C:\Users\Harsh\Anaconda3\envs\myenv\lib\site-packages\django\template\response.py", line 106, in render
    self.content = self.rendered_content
  File "C:\Users\Harsh\Anaconda3\envs\myenv\lib\site-packages\rest_framework\response.py", line 70, in rendered_content
    ret = renderer.render(self.data, accepted_media_type, context)
  File "C:\Users\Harsh\Anaconda3\envs\myenv\lib\site-packages\rest_framework\renderers.py", line 725, in render
    context = self.get_context(data, accepted_media_type, renderer_context)
  File "C:\Users\Harsh\Anaconda3\envs\myenv\lib\site-packages\rest_framework\renderers.py", line 681, in get_context
    'content': self.get_content(renderer, data, accepted_media_type, renderer_context),
  File "C:\Users\Harsh\Anaconda3\envs\myenv\lib\site-packages\rest_framework\renderers.py", line 414, in get_content
    content = renderer.render(data, accepted_media_type, renderer_context)
  File "C:\Users\Harsh\Anaconda3\envs\myenv\lib\site-packages\rest_framework\renderers.py", line 104, in render
    allow_nan=not self.strict, separators=separators
  File "C:\Users\Harsh\Anaconda3\envs\myenv\lib\site-packages\rest_framework\utils\json.py", line 25, in dumps
    return json.dumps(*args, **kwargs)
  File "C:\Users\Harsh\Anaconda3\envs\myenv\lib\json\__init__.py", line 238, in dumps
    **kw).encode(obj)
  File "C:\Users\Harsh\Anaconda3\envs\myenv\lib\json\encoder.py", line 201, in encode
    chunks = list(chunks)
  File "C:\Users\Harsh\Anaconda3\envs\myenv\lib\json\encoder.py", line 439, in _iterencode
    yield from _iterencode(o, _current_indent_level)
  File "C:\Users\Harsh\Anaconda3\envs\myenv\lib\json\encoder.py", line 429, in _iterencode
    yield from _iterencode_list(o, _current_indent_level)
  File "C:\Users\Harsh\Anaconda3\envs\myenv\lib\json\encoder.py", line 325, in _iterencode_list
    yield from chunks
  File "C:\Users\Harsh\Anaconda3\envs\myenv\lib\json\encoder.py", line 438, in _iterencode
    o = _default(o)
  File "C:\Users\Harsh\Anaconda3\envs\myenv\lib\site-packages\rest_framework\utils\encoders.py", line 67, in default
    return super().default(obj)
  File "C:\Users\Harsh\Anaconda3\envs\myenv\lib\json\encoder.py", line 179, in default
    raise TypeError(f'Object of type {o.__class__.__name__} '
TypeError: Object of type Vote_table is not JSON serializable
2019-09-27 12:02:43,881 - INFO - C:\Users\Harsh\PycharmProjects\sad_project\garbage_project\garbage_app\views.py changed, reloading.
2019-09-27 12:02:55,657 - ERROR - Internal Server Error: /upvotelist/
Traceback (most recent call last):
  File "C:\Users\Harsh\Anaconda3\envs\myenv\lib\site-packages\django\core\handlers\exception.py", line 34, in inner
    response = get_response(request)
  File "C:\Users\Harsh\Anaconda3\envs\myenv\lib\site-packages\django\core\handlers\base.py", line 145, in _get_response
    response = self.process_exception_by_middleware(e, request)
  File "C:\Users\Harsh\Anaconda3\envs\myenv\lib\site-packages\django\core\handlers\base.py", line 143, in _get_response
    response = response.render()
  File "C:\Users\Harsh\Anaconda3\envs\myenv\lib\site-packages\django\template\response.py", line 106, in render
    self.content = self.rendered_content
  File "C:\Users\Harsh\Anaconda3\envs\myenv\lib\site-packages\rest_framework\response.py", line 70, in rendered_content
    ret = renderer.render(self.data, accepted_media_type, context)
  File "C:\Users\Harsh\Anaconda3\envs\myenv\lib\site-packages\rest_framework\renderers.py", line 725, in render
    context = self.get_context(data, accepted_media_type, renderer_context)
  File "C:\Users\Harsh\Anaconda3\envs\myenv\lib\site-packages\rest_framework\renderers.py", line 681, in get_context
    'content': self.get_content(renderer, data, accepted_media_type, renderer_context),
  File "C:\Users\Harsh\Anaconda3\envs\myenv\lib\site-packages\rest_framework\renderers.py", line 414, in get_content
    content = renderer.render(data, accepted_media_type, renderer_context)
  File "C:\Users\Harsh\Anaconda3\envs\myenv\lib\site-packages\rest_framework\renderers.py", line 104, in render
    allow_nan=not self.strict, separators=separators
  File "C:\Users\Harsh\Anaconda3\envs\myenv\lib\site-packages\rest_framework\utils\json.py", line 25, in dumps
    return json.dumps(*args, **kwargs)
  File "C:\Users\Harsh\Anaconda3\envs\myenv\lib\json\__init__.py", line 238, in dumps
    **kw).encode(obj)
  File "C:\Users\Harsh\Anaconda3\envs\myenv\lib\json\encoder.py", line 201, in encode
    chunks = list(chunks)
  File "C:\Users\Harsh\Anaconda3\envs\myenv\lib\json\encoder.py", line 431, in _iterencode
    yield from _iterencode_dict(o, _current_indent_level)
  File "C:\Users\Harsh\Anaconda3\envs\myenv\lib\json\encoder.py", line 405, in _iterencode_dict
    yield from chunks
  File "C:\Users\Harsh\Anaconda3\envs\myenv\lib\json\encoder.py", line 439, in _iterencode
    yield from _iterencode(o, _current_indent_level)
  File "C:\Users\Harsh\Anaconda3\envs\myenv\lib\json\encoder.py", line 429, in _iterencode
    yield from _iterencode_list(o, _current_indent_level)
  File "C:\Users\Harsh\Anaconda3\envs\myenv\lib\json\encoder.py", line 325, in _iterencode_list
    yield from chunks
  File "C:\Users\Harsh\Anaconda3\envs\myenv\lib\json\encoder.py", line 438, in _iterencode
    o = _default(o)
  File "C:\Users\Harsh\Anaconda3\envs\myenv\lib\site-packages\rest_framework\utils\encoders.py", line 67, in default
    return super().default(obj)
  File "C:\Users\Harsh\Anaconda3\envs\myenv\lib\json\encoder.py", line 179, in default
    raise TypeError(f'Object of type {o.__class__.__name__} '
TypeError: Object of type Vote_table is not JSON serializable
2019-09-27 12:02:56,939 - ERROR - Internal Server Error: /upvotelist/
Traceback (most recent call last):
  File "C:\Users\Harsh\Anaconda3\envs\myenv\lib\site-packages\django\core\handlers\exception.py", line 34, in inner
    response = get_response(request)
  File "C:\Users\Harsh\Anaconda3\envs\myenv\lib\site-packages\django\core\handlers\base.py", line 145, in _get_response
    response = self.process_exception_by_middleware(e, request)
  File "C:\Users\Harsh\Anaconda3\envs\myenv\lib\site-packages\django\core\handlers\base.py", line 143, in _get_response
    response = response.render()
  File "C:\Users\Harsh\Anaconda3\envs\myenv\lib\site-packages\django\template\response.py", line 106, in render
    self.content = self.rendered_content
  File "C:\Users\Harsh\Anaconda3\envs\myenv\lib\site-packages\rest_framework\response.py", line 70, in rendered_content
    ret = renderer.render(self.data, accepted_media_type, context)
  File "C:\Users\Harsh\Anaconda3\envs\myenv\lib\site-packages\rest_framework\renderers.py", line 725, in render
    context = self.get_context(data, accepted_media_type, renderer_context)
  File "C:\Users\Harsh\Anaconda3\envs\myenv\lib\site-packages\rest_framework\renderers.py", line 681, in get_context
    'content': self.get_content(renderer, data, accepted_media_type, renderer_context),
  File "C:\Users\Harsh\Anaconda3\envs\myenv\lib\site-packages\rest_framework\renderers.py", line 414, in get_content
    content = renderer.render(data, accepted_media_type, renderer_context)
  File "C:\Users\Harsh\Anaconda3\envs\myenv\lib\site-packages\rest_framework\renderers.py", line 104, in render
    allow_nan=not self.strict, separators=separators
  File "C:\Users\Harsh\Anaconda3\envs\myenv\lib\site-packages\rest_framework\utils\json.py", line 25, in dumps
    return json.dumps(*args, **kwargs)
  File "C:\Users\Harsh\Anaconda3\envs\myenv\lib\json\__init__.py", line 238, in dumps
    **kw).encode(obj)
  File "C:\Users\Harsh\Anaconda3\envs\myenv\lib\json\encoder.py", line 201, in encode
    chunks = list(chunks)
  File "C:\Users\Harsh\Anaconda3\envs\myenv\lib\json\encoder.py", line 431, in _iterencode
    yield from _iterencode_dict(o, _current_indent_level)
  File "C:\Users\Harsh\Anaconda3\envs\myenv\lib\json\encoder.py", line 405, in _iterencode_dict
    yield from chunks
  File "C:\Users\Harsh\Anaconda3\envs\myenv\lib\json\encoder.py", line 439, in _iterencode
    yield from _iterencode(o, _current_indent_level)
  File "C:\Users\Harsh\Anaconda3\envs\myenv\lib\json\encoder.py", line 429, in _iterencode
    yield from _iterencode_list(o, _current_indent_level)
  File "C:\Users\Harsh\Anaconda3\envs\myenv\lib\json\encoder.py", line 325, in _iterencode_list
    yield from chunks
  File "C:\Users\Harsh\Anaconda3\envs\myenv\lib\json\encoder.py", line 438, in _iterencode
    o = _default(o)
  File "C:\Users\Harsh\Anaconda3\envs\myenv\lib\site-packages\rest_framework\utils\encoders.py", line 67, in default
    return super().default(obj)
  File "C:\Users\Harsh\Anaconda3\envs\myenv\lib\json\encoder.py", line 179, in default
    raise TypeError(f'Object of type {o.__class__.__name__} '
TypeError: Object of type Vote_table is not JSON serializable
2019-09-27 12:03:04,494 - ERROR - Internal Server Error: /upvotelist/
Traceback (most recent call last):
  File "C:\Users\Harsh\Anaconda3\envs\myenv\lib\site-packages\django\core\handlers\exception.py", line 34, in inner
    response = get_response(request)
  File "C:\Users\Harsh\Anaconda3\envs\myenv\lib\site-packages\django\core\handlers\base.py", line 145, in _get_response
    response = self.process_exception_by_middleware(e, request)
  File "C:\Users\Harsh\Anaconda3\envs\myenv\lib\site-packages\django\core\handlers\base.py", line 143, in _get_response
    response = response.render()
  File "C:\Users\Harsh\Anaconda3\envs\myenv\lib\site-packages\django\template\response.py", line 106, in render
    self.content = self.rendered_content
  File "C:\Users\Harsh\Anaconda3\envs\myenv\lib\site-packages\rest_framework\response.py", line 70, in rendered_content
    ret = renderer.render(self.data, accepted_media_type, context)
  File "C:\Users\Harsh\Anaconda3\envs\myenv\lib\site-packages\rest_framework\renderers.py", line 725, in render
    context = self.get_context(data, accepted_media_type, renderer_context)
  File "C:\Users\Harsh\Anaconda3\envs\myenv\lib\site-packages\rest_framework\renderers.py", line 681, in get_context
    'content': self.get_content(renderer, data, accepted_media_type, renderer_context),
  File "C:\Users\Harsh\Anaconda3\envs\myenv\lib\site-packages\rest_framework\renderers.py", line 414, in get_content
    content = renderer.render(data, accepted_media_type, renderer_context)
  File "C:\Users\Harsh\Anaconda3\envs\myenv\lib\site-packages\rest_framework\renderers.py", line 104, in render
    allow_nan=not self.strict, separators=separators
  File "C:\Users\Harsh\Anaconda3\envs\myenv\lib\site-packages\rest_framework\utils\json.py", line 25, in dumps
    return json.dumps(*args, **kwargs)
  File "C:\Users\Harsh\Anaconda3\envs\myenv\lib\json\__init__.py", line 238, in dumps
    **kw).encode(obj)
  File "C:\Users\Harsh\Anaconda3\envs\myenv\lib\json\encoder.py", line 201, in encode
    chunks = list(chunks)
  File "C:\Users\Harsh\Anaconda3\envs\myenv\lib\json\encoder.py", line 431, in _iterencode
    yield from _iterencode_dict(o, _current_indent_level)
  File "C:\Users\Harsh\Anaconda3\envs\myenv\lib\json\encoder.py", line 405, in _iterencode_dict
    yield from chunks
  File "C:\Users\Harsh\Anaconda3\envs\myenv\lib\json\encoder.py", line 439, in _iterencode
    yield from _iterencode(o, _current_indent_level)
  File "C:\Users\Harsh\Anaconda3\envs\myenv\lib\json\encoder.py", line 429, in _iterencode
    yield from _iterencode_list(o, _current_indent_level)
  File "C:\Users\Harsh\Anaconda3\envs\myenv\lib\json\encoder.py", line 325, in _iterencode_list
    yield from chunks
  File "C:\Users\Harsh\Anaconda3\envs\myenv\lib\json\encoder.py", line 438, in _iterencode
    o = _default(o)
  File "C:\Users\Harsh\Anaconda3\envs\myenv\lib\site-packages\rest_framework\utils\encoders.py", line 67, in default
    return super().default(obj)
  File "C:\Users\Harsh\Anaconda3\envs\myenv\lib\json\encoder.py", line 179, in default
    raise TypeError(f'Object of type {o.__class__.__name__} '
TypeError: Object of type Vote_table is not JSON serializable
2019-09-27 12:05:02,932 - ERROR - Internal Server Error: /upvotelist/
Traceback (most recent call last):
  File "C:\Users\Harsh\Anaconda3\envs\myenv\lib\site-packages\django\core\handlers\exception.py", line 34, in inner
    response = get_response(request)
  File "C:\Users\Harsh\Anaconda3\envs\myenv\lib\site-packages\django\core\handlers\base.py", line 145, in _get_response
    response = self.process_exception_by_middleware(e, request)
  File "C:\Users\Harsh\Anaconda3\envs\myenv\lib\site-packages\django\core\handlers\base.py", line 143, in _get_response
    response = response.render()
  File "C:\Users\Harsh\Anaconda3\envs\myenv\lib\site-packages\django\template\response.py", line 106, in render
    self.content = self.rendered_content
  File "C:\Users\Harsh\Anaconda3\envs\myenv\lib\site-packages\rest_framework\response.py", line 70, in rendered_content
    ret = renderer.render(self.data, accepted_media_type, context)
  File "C:\Users\Harsh\Anaconda3\envs\myenv\lib\site-packages\rest_framework\renderers.py", line 725, in render
    context = self.get_context(data, accepted_media_type, renderer_context)
  File "C:\Users\Harsh\Anaconda3\envs\myenv\lib\site-packages\rest_framework\renderers.py", line 681, in get_context
    'content': self.get_content(renderer, data, accepted_media_type, renderer_context),
  File "C:\Users\Harsh\Anaconda3\envs\myenv\lib\site-packages\rest_framework\renderers.py", line 414, in get_content
    content = renderer.render(data, accepted_media_type, renderer_context)
  File "C:\Users\Harsh\Anaconda3\envs\myenv\lib\site-packages\rest_framework\renderers.py", line 104, in render
    allow_nan=not self.strict, separators=separators
  File "C:\Users\Harsh\Anaconda3\envs\myenv\lib\site-packages\rest_framework\utils\json.py", line 25, in dumps
    return json.dumps(*args, **kwargs)
  File "C:\Users\Harsh\Anaconda3\envs\myenv\lib\json\__init__.py", line 238, in dumps
    **kw).encode(obj)
  File "C:\Users\Harsh\Anaconda3\envs\myenv\lib\json\encoder.py", line 201, in encode
    chunks = list(chunks)
  File "C:\Users\Harsh\Anaconda3\envs\myenv\lib\json\encoder.py", line 431, in _iterencode
    yield from _iterencode_dict(o, _current_indent_level)
  File "C:\Users\Harsh\Anaconda3\envs\myenv\lib\json\encoder.py", line 405, in _iterencode_dict
    yield from chunks
  File "C:\Users\Harsh\Anaconda3\envs\myenv\lib\json\encoder.py", line 439, in _iterencode
    yield from _iterencode(o, _current_indent_level)
  File "C:\Users\Harsh\Anaconda3\envs\myenv\lib\json\encoder.py", line 429, in _iterencode
    yield from _iterencode_list(o, _current_indent_level)
  File "C:\Users\Harsh\Anaconda3\envs\myenv\lib\json\encoder.py", line 325, in _iterencode_list
    yield from chunks
  File "C:\Users\Harsh\Anaconda3\envs\myenv\lib\json\encoder.py", line 438, in _iterencode
    o = _default(o)
  File "C:\Users\Harsh\Anaconda3\envs\myenv\lib\site-packages\rest_framework\utils\encoders.py", line 67, in default
    return super().default(obj)
  File "C:\Users\Harsh\Anaconda3\envs\myenv\lib\json\encoder.py", line 179, in default
    raise TypeError(f'Object of type {o.__class__.__name__} '
TypeError: Object of type Vote_table is not JSON serializable
2019-09-27 12:06:10,107 - WARNING - Method Not Allowed: /upvote/
2019-09-27 12:09:25,666 - INFO - C:\Users\Harsh\PycharmProjects\sad_project\garbage_project\garbage_app\views.py changed, reloading.
2019-09-27 12:09:32,849 - ERROR - Internal Server Error: /upvotelist/
Traceback (most recent call last):
  File "C:\Users\Harsh\Anaconda3\envs\myenv\lib\site-packages\django\core\handlers\exception.py", line 34, in inner
    response = get_response(request)
  File "C:\Users\Harsh\Anaconda3\envs\myenv\lib\site-packages\django\core\handlers\base.py", line 115, in _get_response
    response = self.process_exception_by_middleware(e, request)
  File "C:\Users\Harsh\Anaconda3\envs\myenv\lib\site-packages\django\core\handlers\base.py", line 113, in _get_response
    response = wrapped_callback(request, *callback_args, **callback_kwargs)
  File "C:\Users\Harsh\Anaconda3\envs\myenv\lib\site-packages\django\views\decorators\csrf.py", line 54, in wrapped_view
    return view_func(*args, **kwargs)
  File "C:\Users\Harsh\Anaconda3\envs\myenv\lib\site-packages\django\views\generic\base.py", line 71, in view
    return self.dispatch(request, *args, **kwargs)
  File "C:\Users\Harsh\Anaconda3\envs\myenv\lib\site-packages\rest_framework\views.py", line 505, in dispatch
    response = self.handle_exception(exc)
  File "C:\Users\Harsh\Anaconda3\envs\myenv\lib\site-packages\rest_framework\views.py", line 465, in handle_exception
    self.raise_uncaught_exception(exc)
  File "C:\Users\Harsh\Anaconda3\envs\myenv\lib\site-packages\rest_framework\views.py", line 476, in raise_uncaught_exception
    raise exc
  File "C:\Users\Harsh\Anaconda3\envs\myenv\lib\site-packages\rest_framework\views.py", line 502, in dispatch
    response = handler(request, *args, **kwargs)
  File "C:\Users\Harsh\Anaconda3\envs\myenv\lib\site-packages\rest_framework\decorators.py", line 50, in handler
    return func(*args, **kwargs)
  File "C:\Users\Harsh\PycharmProjects\sad_project\garbage_project\garbage_app\views.py", line 182, in Vote_table_list
    return Response(serializer)
  File "C:\Users\Harsh\Anaconda3\envs\myenv\lib\site-packages\rest_framework\response.py", line 38, in __init__
    raise AssertionError(msg)
AssertionError: You passed a Serializer instance as data, but probably meant to pass serialized `.data` or `.error`. representation.
2019-09-27 12:10:01,158 - INFO - C:\Users\Harsh\PycharmProjects\sad_project\garbage_project\garbage_app\views.py changed, reloading.
2019-09-27 12:10:05,253 - ERROR - Internal Server Error: /upvotelist/
Traceback (most recent call last):
  File "C:\Users\Harsh\Anaconda3\envs\myenv\lib\site-packages\django\core\handlers\exception.py", line 34, in inner
    response = get_response(request)
  File "C:\Users\Harsh\Anaconda3\envs\myenv\lib\site-packages\django\core\handlers\base.py", line 115, in _get_response
    response = self.process_exception_by_middleware(e, request)
  File "C:\Users\Harsh\Anaconda3\envs\myenv\lib\site-packages\django\core\handlers\base.py", line 113, in _get_response
    response = wrapped_callback(request, *callback_args, **callback_kwargs)
  File "C:\Users\Harsh\Anaconda3\envs\myenv\lib\site-packages\django\views\decorators\csrf.py", line 54, in wrapped_view
    return view_func(*args, **kwargs)
  File "C:\Users\Harsh\Anaconda3\envs\myenv\lib\site-packages\django\views\generic\base.py", line 71, in view
    return self.dispatch(request, *args, **kwargs)
  File "C:\Users\Harsh\Anaconda3\envs\myenv\lib\site-packages\rest_framework\views.py", line 505, in dispatch
    response = self.handle_exception(exc)
  File "C:\Users\Harsh\Anaconda3\envs\myenv\lib\site-packages\rest_framework\views.py", line 465, in handle_exception
    self.raise_uncaught_exception(exc)
  File "C:\Users\Harsh\Anaconda3\envs\myenv\lib\site-packages\rest_framework\views.py", line 476, in raise_uncaught_exception
    raise exc
  File "C:\Users\Harsh\Anaconda3\envs\myenv\lib\site-packages\rest_framework\views.py", line 502, in dispatch
    response = handler(request, *args, **kwargs)
  File "C:\Users\Harsh\Anaconda3\envs\myenv\lib\site-packages\rest_framework\decorators.py", line 50, in handler
    return func(*args, **kwargs)
  File "C:\Users\Harsh\PycharmProjects\sad_project\garbage_project\garbage_app\views.py", line 182, in Vote_table_list
    return Response(serializer.data)
  File "C:\Users\Harsh\Anaconda3\envs\myenv\lib\site-packages\rest_framework\serializers.py", line 559, in data
    ret = super().data
  File "C:\Users\Harsh\Anaconda3\envs\myenv\lib\site-packages\rest_framework\serializers.py", line 257, in data
    raise AssertionError(msg)
AssertionError: When a serializer is passed a `data` keyword argument you must call `.is_valid()` before attempting to access the serialized `.data` representation.
You should either call `.is_valid()` first, or access `.initial_data` instead.
2019-09-27 12:11:07,510 - INFO - C:\Users\Harsh\PycharmProjects\sad_project\garbage_project\garbage_app\views.py changed, reloading.
2019-09-27 12:11:10,544 - ERROR - Internal Server Error: /upvotelist/
Traceback (most recent call last):
  File "C:\Users\Harsh\Anaconda3\envs\myenv\lib\site-packages\django\core\handlers\exception.py", line 34, in inner
    response = get_response(request)
  File "C:\Users\Harsh\Anaconda3\envs\myenv\lib\site-packages\django\core\handlers\base.py", line 115, in _get_response
    response = self.process_exception_by_middleware(e, request)
  File "C:\Users\Harsh\Anaconda3\envs\myenv\lib\site-packages\django\core\handlers\base.py", line 113, in _get_response
    response = wrapped_callback(request, *callback_args, **callback_kwargs)
  File "C:\Users\Harsh\Anaconda3\envs\myenv\lib\site-packages\django\views\decorators\csrf.py", line 54, in wrapped_view
    return view_func(*args, **kwargs)
  File "C:\Users\Harsh\Anaconda3\envs\myenv\lib\site-packages\django\views\generic\base.py", line 71, in view
    return self.dispatch(request, *args, **kwargs)
  File "C:\Users\Harsh\Anaconda3\envs\myenv\lib\site-packages\rest_framework\views.py", line 507, in dispatch
    self.response = self.finalize_response(request, response, *args, **kwargs)
  File "C:\Users\Harsh\Anaconda3\envs\myenv\lib\site-packages\rest_framework\views.py", line 422, in finalize_response
    % type(response)
AssertionError: Expected a `Response`, `HttpResponse` or `HttpStreamingResponse` to be returned from the view, but received a `<class 'dict'>`
2019-09-27 12:11:12,543 - ERROR - Internal Server Error: /upvotelist/
Traceback (most recent call last):
  File "C:\Users\Harsh\Anaconda3\envs\myenv\lib\site-packages\django\core\handlers\exception.py", line 34, in inner
    response = get_response(request)
  File "C:\Users\Harsh\Anaconda3\envs\myenv\lib\site-packages\django\core\handlers\base.py", line 115, in _get_response
    response = self.process_exception_by_middleware(e, request)
  File "C:\Users\Harsh\Anaconda3\envs\myenv\lib\site-packages\django\core\handlers\base.py", line 113, in _get_response
    response = wrapped_callback(request, *callback_args, **callback_kwargs)
  File "C:\Users\Harsh\Anaconda3\envs\myenv\lib\site-packages\django\views\decorators\csrf.py", line 54, in wrapped_view
    return view_func(*args, **kwargs)
  File "C:\Users\Harsh\Anaconda3\envs\myenv\lib\site-packages\django\views\generic\base.py", line 71, in view
    return self.dispatch(request, *args, **kwargs)
  File "C:\Users\Harsh\Anaconda3\envs\myenv\lib\site-packages\rest_framework\views.py", line 507, in dispatch
    self.response = self.finalize_response(request, response, *args, **kwargs)
  File "C:\Users\Harsh\Anaconda3\envs\myenv\lib\site-packages\rest_framework\views.py", line 422, in finalize_response
    % type(response)
AssertionError: Expected a `Response`, `HttpResponse` or `HttpStreamingResponse` to be returned from the view, but received a `<class 'dict'>`
2019-09-27 12:11:58,579 - INFO - C:\Users\Harsh\PycharmProjects\sad_project\garbage_project\garbage_app\views.py changed, reloading.
2019-09-27 12:12:42,910 - WARNING - Method Not Allowed: /upvote/
2019-09-27 12:14:19,270 - WARNING - Bad Request: /upvote/
2019-09-27 12:20:45,729 - INFO - C:\Users\Harsh\PycharmProjects\sad_project\garbage_project\garbage_app\views.py changed, reloading.
2019-09-27 12:20:45,805 - INFO - C:\Users\Harsh\PycharmProjects\sad_project\garbage_project\garbage_app\views.py changed, reloading.
2019-09-27 12:21:03,455 - ERROR - Internal Server Error: /upvote/
Traceback (most recent call last):
  File "C:\Users\Harsh\Anaconda3\envs\myenv\lib\site-packages\django\core\handlers\exception.py", line 34, in inner
    response = get_response(request)
  File "C:\Users\Harsh\Anaconda3\envs\myenv\lib\site-packages\django\core\handlers\base.py", line 145, in _get_response
    response = self.process_exception_by_middleware(e, request)
  File "C:\Users\Harsh\Anaconda3\envs\myenv\lib\site-packages\django\core\handlers\base.py", line 143, in _get_response
    response = response.render()
  File "C:\Users\Harsh\Anaconda3\envs\myenv\lib\site-packages\django\template\response.py", line 106, in render
    self.content = self.rendered_content
  File "C:\Users\Harsh\Anaconda3\envs\myenv\lib\site-packages\rest_framework\response.py", line 70, in rendered_content
    ret = renderer.render(self.data, accepted_media_type, context)
  File "C:\Users\Harsh\Anaconda3\envs\myenv\lib\site-packages\rest_framework\renderers.py", line 725, in render
    context = self.get_context(data, accepted_media_type, renderer_context)
  File "C:\Users\Harsh\Anaconda3\envs\myenv\lib\site-packages\rest_framework\renderers.py", line 681, in get_context
    'content': self.get_content(renderer, data, accepted_media_type, renderer_context),
  File "C:\Users\Harsh\Anaconda3\envs\myenv\lib\site-packages\rest_framework\renderers.py", line 414, in get_content
    content = renderer.render(data, accepted_media_type, renderer_context)
  File "C:\Users\Harsh\Anaconda3\envs\myenv\lib\site-packages\rest_framework\renderers.py", line 104, in render
    allow_nan=not self.strict, separators=separators
  File "C:\Users\Harsh\Anaconda3\envs\myenv\lib\site-packages\rest_framework\utils\json.py", line 25, in dumps
    return json.dumps(*args, **kwargs)
  File "C:\Users\Harsh\Anaconda3\envs\myenv\lib\json\__init__.py", line 238, in dumps
    **kw).encode(obj)
  File "C:\Users\Harsh\Anaconda3\envs\myenv\lib\json\encoder.py", line 201, in encode
    chunks = list(chunks)
  File "C:\Users\Harsh\Anaconda3\envs\myenv\lib\json\encoder.py", line 438, in _iterencode
    o = _default(o)
  File "C:\Users\Harsh\Anaconda3\envs\myenv\lib\site-packages\rest_framework\utils\encoders.py", line 67, in default
    return super().default(obj)
  File "C:\Users\Harsh\Anaconda3\envs\myenv\lib\json\encoder.py", line 179, in default
    raise TypeError(f'Object of type {o.__class__.__name__} '
TypeError: Object of type Post is not JSON serializable
2019-09-27 12:21:03,558 - WARNING - Method Not Allowed: /upvote/
2019-09-27 12:21:30,940 - ERROR - Internal Server Error: /upvote/
Traceback (most recent call last):
  File "C:\Users\Harsh\Anaconda3\envs\myenv\lib\site-packages\django\core\handlers\exception.py", line 34, in inner
    response = get_response(request)
  File "C:\Users\Harsh\Anaconda3\envs\myenv\lib\site-packages\django\core\handlers\base.py", line 145, in _get_response
    response = self.process_exception_by_middleware(e, request)
  File "C:\Users\Harsh\Anaconda3\envs\myenv\lib\site-packages\django\core\handlers\base.py", line 143, in _get_response
    response = response.render()
  File "C:\Users\Harsh\Anaconda3\envs\myenv\lib\site-packages\django\template\response.py", line 106, in render
    self.content = self.rendered_content
  File "C:\Users\Harsh\Anaconda3\envs\myenv\lib\site-packages\rest_framework\response.py", line 70, in rendered_content
    ret = renderer.render(self.data, accepted_media_type, context)
  File "C:\Users\Harsh\Anaconda3\envs\myenv\lib\site-packages\rest_framework\renderers.py", line 725, in render
    context = self.get_context(data, accepted_media_type, renderer_context)
  File "C:\Users\Harsh\Anaconda3\envs\myenv\lib\site-packages\rest_framework\renderers.py", line 681, in get_context
    'content': self.get_content(renderer, data, accepted_media_type, renderer_context),
  File "C:\Users\Harsh\Anaconda3\envs\myenv\lib\site-packages\rest_framework\renderers.py", line 414, in get_content
    content = renderer.render(data, accepted_media_type, renderer_context)
  File "C:\Users\Harsh\Anaconda3\envs\myenv\lib\site-packages\rest_framework\renderers.py", line 104, in render
    allow_nan=not self.strict, separators=separators
  File "C:\Users\Harsh\Anaconda3\envs\myenv\lib\site-packages\rest_framework\utils\json.py", line 25, in dumps
    return json.dumps(*args, **kwargs)
  File "C:\Users\Harsh\Anaconda3\envs\myenv\lib\json\__init__.py", line 238, in dumps
    **kw).encode(obj)
  File "C:\Users\Harsh\Anaconda3\envs\myenv\lib\json\encoder.py", line 201, in encode
    chunks = list(chunks)
  File "C:\Users\Harsh\Anaconda3\envs\myenv\lib\json\encoder.py", line 438, in _iterencode
    o = _default(o)
  File "C:\Users\Harsh\Anaconda3\envs\myenv\lib\site-packages\rest_framework\utils\encoders.py", line 67, in default
    return super().default(obj)
  File "C:\Users\Harsh\Anaconda3\envs\myenv\lib\json\encoder.py", line 179, in default
    raise TypeError(f'Object of type {o.__class__.__name__} '
TypeError: Object of type Post is not JSON serializable
2019-09-27 12:21:31,009 - WARNING - Method Not Allowed: /upvote/
2019-09-27 12:22:24,898 - INFO - C:\Users\Harsh\PycharmProjects\sad_project\garbage_project\garbage_app\views.py changed, reloading.
2019-09-27 12:22:25,003 - INFO - C:\Users\Harsh\PycharmProjects\sad_project\garbage_project\garbage_app\views.py changed, reloading.
2019-09-27 12:23:09,674 - INFO - C:\Users\Harsh\PycharmProjects\sad_project\garbage_project\garbage_app\views.py changed, reloading.
2019-09-27 12:23:09,720 - INFO - C:\Users\Harsh\PycharmProjects\sad_project\garbage_project\garbage_app\views.py changed, reloading.
2019-09-27 12:28:41,600 - INFO - C:\Users\Harsh\PycharmProjects\sad_project\garbage_project\garbage_app\views.py changed, reloading.
2019-09-27 12:28:41,606 - INFO - C:\Users\Harsh\PycharmProjects\sad_project\garbage_project\garbage_app\views.py changed, reloading.
2019-09-27 12:28:58,187 - DEBUG - Data Received
2019-09-27 12:31:55,435 - INFO - C:\Users\Harsh\PycharmProjects\sad_project\garbage_project\garbage_app\views.py changed, reloading.
2019-09-27 12:31:55,466 - INFO - C:\Users\Harsh\PycharmProjects\sad_project\garbage_project\garbage_app\views.py changed, reloading.
2019-09-27 12:32:10,697 - DEBUG - Data Received
2019-09-27 12:32:10,730 - CRITICAL - 'Post' object is not subscriptable
Traceback (most recent call last):
  File "C:\Users\Harsh\PycharmProjects\sad_project\garbage_project\garbage_app\views.py", line 158, in upvote_view
    post_obj["vote_count"] += 1
TypeError: 'Post' object is not subscriptable
2019-09-27 12:33:07,326 - INFO - C:\Users\Harsh\PycharmProjects\sad_project\garbage_project\garbage_app\views.py changed, reloading.
2019-09-27 12:33:07,360 - INFO - C:\Users\Harsh\PycharmProjects\sad_project\garbage_project\garbage_app\views.py changed, reloading.
2019-09-27 12:33:28,455 - DEBUG - Data Received
2019-09-27 12:33:28,505 - CRITICAL - UNIQUE constraint failed: garbage_app_post.id
Traceback (most recent call last):
  File "C:\Users\Harsh\Anaconda3\envs\myenv\lib\site-packages\django\db\backends\utils.py", line 84, in _execute
    return self.cursor.execute(sql, params)
  File "C:\Users\Harsh\Anaconda3\envs\myenv\lib\site-packages\django\db\backends\sqlite3\base.py", line 383, in execute
    return Database.Cursor.execute(self, query, params)
sqlite3.IntegrityError: UNIQUE constraint failed: garbage_app_post.id

The above exception was the direct cause of the following exception:

Traceback (most recent call last):
  File "C:\Users\Harsh\PycharmProjects\sad_project\garbage_project\garbage_app\views.py", line 159, in upvote_view
    post_obj.save(["vote_count"])
  File "C:\Users\Harsh\Anaconda3\envs\myenv\lib\site-packages\django\db\models\base.py", line 741, in save
    force_update=force_update, update_fields=update_fields)
  File "C:\Users\Harsh\Anaconda3\envs\myenv\lib\site-packages\django\db\models\base.py", line 779, in save_base
    force_update, using, update_fields,
  File "C:\Users\Harsh\Anaconda3\envs\myenv\lib\site-packages\django\db\models\base.py", line 870, in _save_table
    result = self._do_insert(cls._base_manager, using, fields, update_pk, raw)
  File "C:\Users\Harsh\Anaconda3\envs\myenv\lib\site-packages\django\db\models\base.py", line 908, in _do_insert
    using=using, raw=raw)
  File "C:\Users\Harsh\Anaconda3\envs\myenv\lib\site-packages\django\db\models\manager.py", line 82, in manager_method
    return getattr(self.get_queryset(), name)(*args, **kwargs)
  File "C:\Users\Harsh\Anaconda3\envs\myenv\lib\site-packages\django\db\models\query.py", line 1186, in _insert
    return query.get_compiler(using=using).execute_sql(return_id)
  File "C:\Users\Harsh\Anaconda3\envs\myenv\lib\site-packages\django\db\models\sql\compiler.py", line 1335, in execute_sql
    cursor.execute(sql, params)
  File "C:\Users\Harsh\Anaconda3\envs\myenv\lib\site-packages\django\db\backends\utils.py", line 99, in execute
    return super().execute(sql, params)
  File "C:\Users\Harsh\Anaconda3\envs\myenv\lib\site-packages\django\db\backends\utils.py", line 67, in execute
    return self._execute_with_wrappers(sql, params, many=False, executor=self._execute)
  File "C:\Users\Harsh\Anaconda3\envs\myenv\lib\site-packages\django\db\backends\utils.py", line 76, in _execute_with_wrappers
    return executor(sql, params, many, context)
  File "C:\Users\Harsh\Anaconda3\envs\myenv\lib\site-packages\django\db\backends\utils.py", line 84, in _execute
    return self.cursor.execute(sql, params)
  File "C:\Users\Harsh\Anaconda3\envs\myenv\lib\site-packages\django\db\utils.py", line 89, in __exit__
    raise dj_exc_value.with_traceback(traceback) from exc_value
  File "C:\Users\Harsh\Anaconda3\envs\myenv\lib\site-packages\django\db\backends\utils.py", line 84, in _execute
    return self.cursor.execute(sql, params)
  File "C:\Users\Harsh\Anaconda3\envs\myenv\lib\site-packages\django\db\backends\sqlite3\base.py", line 383, in execute
    return Database.Cursor.execute(self, query, params)
django.db.utils.IntegrityError: UNIQUE constraint failed: garbage_app_post.id
2019-09-27 12:40:01,451 - INFO - C:\Users\Harsh\PycharmProjects\sad_project\garbage_project\garbage_app\views.py changed, reloading.
2019-09-27 12:40:01,457 - INFO - C:\Users\Harsh\PycharmProjects\sad_project\garbage_project\garbage_app\views.py changed, reloading.
2019-09-27 12:40:10,400 - INFO - C:\Users\Harsh\PycharmProjects\sad_project\garbage_project\garbage_app\views.py changed, reloading.
2019-09-27 12:40:10,435 - INFO - C:\Users\Harsh\PycharmProjects\sad_project\garbage_project\garbage_app\views.py changed, reloading.
2019-09-27 12:40:18,791 - DEBUG - Data Received
2019-09-27 12:40:18,795 - DEBUG - Data Received
2019-09-27 12:40:18,811 - CRITICAL - UNIQUE constraint failed: garbage_app_post.id
Traceback (most recent call last):
  File "C:\Users\Harsh\Anaconda3\envs\myenv\lib\site-packages\django\db\backends\utils.py", line 84, in _execute
    return self.cursor.execute(sql, params)
  File "C:\Users\Harsh\Anaconda3\envs\myenv\lib\site-packages\django\db\backends\sqlite3\base.py", line 383, in execute
    return Database.Cursor.execute(self, query, params)
sqlite3.IntegrityError: UNIQUE constraint failed: garbage_app_post.id

The above exception was the direct cause of the following exception:

Traceback (most recent call last):
  File "C:\Users\Harsh\PycharmProjects\sad_project\garbage_project\garbage_app\views.py", line 160, in upvote_view
    post_obj.save(["vote_count"])
  File "C:\Users\Harsh\Anaconda3\envs\myenv\lib\site-packages\django\db\models\base.py", line 741, in save
    force_update=force_update, update_fields=update_fields)
  File "C:\Users\Harsh\Anaconda3\envs\myenv\lib\site-packages\django\db\models\base.py", line 779, in save_base
    force_update, using, update_fields,
  File "C:\Users\Harsh\Anaconda3\envs\myenv\lib\site-packages\django\db\models\base.py", line 870, in _save_table
    result = self._do_insert(cls._base_manager, using, fields, update_pk, raw)
  File "C:\Users\Harsh\Anaconda3\envs\myenv\lib\site-packages\django\db\models\base.py", line 908, in _do_insert
    using=using, raw=raw)
  File "C:\Users\Harsh\Anaconda3\envs\myenv\lib\site-packages\django\db\models\manager.py", line 82, in manager_method
    return getattr(self.get_queryset(), name)(*args, **kwargs)
  File "C:\Users\Harsh\Anaconda3\envs\myenv\lib\site-packages\django\db\models\query.py", line 1186, in _insert
    return query.get_compiler(using=using).execute_sql(return_id)
  File "C:\Users\Harsh\Anaconda3\envs\myenv\lib\site-packages\django\db\models\sql\compiler.py", line 1335, in execute_sql
    cursor.execute(sql, params)
  File "C:\Users\Harsh\Anaconda3\envs\myenv\lib\site-packages\django\db\backends\utils.py", line 99, in execute
    return super().execute(sql, params)
  File "C:\Users\Harsh\Anaconda3\envs\myenv\lib\site-packages\django\db\backends\utils.py", line 67, in execute
    return self._execute_with_wrappers(sql, params, many=False, executor=self._execute)
  File "C:\Users\Harsh\Anaconda3\envs\myenv\lib\site-packages\django\db\backends\utils.py", line 76, in _execute_with_wrappers
    return executor(sql, params, many, context)
  File "C:\Users\Harsh\Anaconda3\envs\myenv\lib\site-packages\django\db\backends\utils.py", line 84, in _execute
    return self.cursor.execute(sql, params)
  File "C:\Users\Harsh\Anaconda3\envs\myenv\lib\site-packages\django\db\utils.py", line 89, in __exit__
    raise dj_exc_value.with_traceback(traceback) from exc_value
  File "C:\Users\Harsh\Anaconda3\envs\myenv\lib\site-packages\django\db\backends\utils.py", line 84, in _execute
    return self.cursor.execute(sql, params)
  File "C:\Users\Harsh\Anaconda3\envs\myenv\lib\site-packages\django\db\backends\sqlite3\base.py", line 383, in execute
    return Database.Cursor.execute(self, query, params)
django.db.utils.IntegrityError: UNIQUE constraint failed: garbage_app_post.id
2019-09-27 12:42:26,038 - WARNING - Bad Request: /upvote/
2019-09-27 12:42:34,605 - DEBUG - Data Received
2019-09-27 12:42:34,605 - DEBUG - Data Received
2019-09-27 12:42:34,629 - CRITICAL - UNIQUE constraint failed: garbage_app_post.id
Traceback (most recent call last):
  File "C:\Users\Harsh\Anaconda3\envs\myenv\lib\site-packages\django\db\backends\utils.py", line 84, in _execute
    return self.cursor.execute(sql, params)
  File "C:\Users\Harsh\Anaconda3\envs\myenv\lib\site-packages\django\db\backends\sqlite3\base.py", line 383, in execute
    return Database.Cursor.execute(self, query, params)
sqlite3.IntegrityError: UNIQUE constraint failed: garbage_app_post.id

The above exception was the direct cause of the following exception:

Traceback (most recent call last):
  File "C:\Users\Harsh\PycharmProjects\sad_project\garbage_project\garbage_app\views.py", line 160, in upvote_view
    post_obj.save(["vote_count"])
  File "C:\Users\Harsh\Anaconda3\envs\myenv\lib\site-packages\django\db\models\base.py", line 741, in save
    force_update=force_update, update_fields=update_fields)
  File "C:\Users\Harsh\Anaconda3\envs\myenv\lib\site-packages\django\db\models\base.py", line 779, in save_base
    force_update, using, update_fields,
  File "C:\Users\Harsh\Anaconda3\envs\myenv\lib\site-packages\django\db\models\base.py", line 870, in _save_table
    result = self._do_insert(cls._base_manager, using, fields, update_pk, raw)
  File "C:\Users\Harsh\Anaconda3\envs\myenv\lib\site-packages\django\db\models\base.py", line 908, in _do_insert
    using=using, raw=raw)
  File "C:\Users\Harsh\Anaconda3\envs\myenv\lib\site-packages\django\db\models\manager.py", line 82, in manager_method
    return getattr(self.get_queryset(), name)(*args, **kwargs)
  File "C:\Users\Harsh\Anaconda3\envs\myenv\lib\site-packages\django\db\models\query.py", line 1186, in _insert
    return query.get_compiler(using=using).execute_sql(return_id)
  File "C:\Users\Harsh\Anaconda3\envs\myenv\lib\site-packages\django\db\models\sql\compiler.py", line 1335, in execute_sql
    cursor.execute(sql, params)
  File "C:\Users\Harsh\Anaconda3\envs\myenv\lib\site-packages\django\db\backends\utils.py", line 99, in execute
    return super().execute(sql, params)
  File "C:\Users\Harsh\Anaconda3\envs\myenv\lib\site-packages\django\db\backends\utils.py", line 67, in execute
    return self._execute_with_wrappers(sql, params, many=False, executor=self._execute)
  File "C:\Users\Harsh\Anaconda3\envs\myenv\lib\site-packages\django\db\backends\utils.py", line 76, in _execute_with_wrappers
    return executor(sql, params, many, context)
  File "C:\Users\Harsh\Anaconda3\envs\myenv\lib\site-packages\django\db\backends\utils.py", line 84, in _execute
    return self.cursor.execute(sql, params)
  File "C:\Users\Harsh\Anaconda3\envs\myenv\lib\site-packages\django\db\utils.py", line 89, in __exit__
    raise dj_exc_value.with_traceback(traceback) from exc_value
  File "C:\Users\Harsh\Anaconda3\envs\myenv\lib\site-packages\django\db\backends\utils.py", line 84, in _execute
    return self.cursor.execute(sql, params)
  File "C:\Users\Harsh\Anaconda3\envs\myenv\lib\site-packages\django\db\backends\sqlite3\base.py", line 383, in execute
    return Database.Cursor.execute(self, query, params)
django.db.utils.IntegrityError: UNIQUE constraint failed: garbage_app_post.id
2019-09-27 12:44:08,247 - INFO - C:\Users\Harsh\PycharmProjects\sad_project\garbage_project\garbage_app\views.py changed, reloading.
2019-09-27 12:44:08,261 - INFO - C:\Users\Harsh\PycharmProjects\sad_project\garbage_project\garbage_app\views.py changed, reloading.
2019-09-27 12:44:16,963 - INFO - C:\Users\Harsh\PycharmProjects\sad_project\garbage_project\garbage_app\views.py changed, reloading.
2019-09-27 12:44:16,994 - INFO - C:\Users\Harsh\PycharmProjects\sad_project\garbage_project\garbage_app\views.py changed, reloading.
2019-09-27 12:44:20,681 - INFO - C:\Users\Harsh\PycharmProjects\sad_project\garbage_project\garbage_app\views.py changed, reloading.
2019-09-27 12:44:20,691 - INFO - C:\Users\Harsh\PycharmProjects\sad_project\garbage_project\garbage_app\views.py changed, reloading.
2019-09-27 12:44:31,636 - DEBUG - Data Received
2019-09-27 12:44:31,636 - DEBUG - 5
2019-09-27 12:44:31,662 - CRITICAL - UNIQUE constraint failed: garbage_app_post.id
Traceback (most recent call last):
  File "C:\Users\Harsh\Anaconda3\envs\myenv\lib\site-packages\django\db\backends\utils.py", line 84, in _execute
    return self.cursor.execute(sql, params)
  File "C:\Users\Harsh\Anaconda3\envs\myenv\lib\site-packages\django\db\backends\sqlite3\base.py", line 383, in execute
    return Database.Cursor.execute(self, query, params)
sqlite3.IntegrityError: UNIQUE constraint failed: garbage_app_post.id

The above exception was the direct cause of the following exception:

Traceback (most recent call last):
  File "C:\Users\Harsh\PycharmProjects\sad_project\garbage_project\garbage_app\views.py", line 160, in upvote_view
    post_obj.save(["vote_count"])
  File "C:\Users\Harsh\Anaconda3\envs\myenv\lib\site-packages\django\db\models\base.py", line 741, in save
    force_update=force_update, update_fields=update_fields)
  File "C:\Users\Harsh\Anaconda3\envs\myenv\lib\site-packages\django\db\models\base.py", line 779, in save_base
    force_update, using, update_fields,
  File "C:\Users\Harsh\Anaconda3\envs\myenv\lib\site-packages\django\db\models\base.py", line 870, in _save_table
    result = self._do_insert(cls._base_manager, using, fields, update_pk, raw)
  File "C:\Users\Harsh\Anaconda3\envs\myenv\lib\site-packages\django\db\models\base.py", line 908, in _do_insert
    using=using, raw=raw)
  File "C:\Users\Harsh\Anaconda3\envs\myenv\lib\site-packages\django\db\models\manager.py", line 82, in manager_method
    return getattr(self.get_queryset(), name)(*args, **kwargs)
  File "C:\Users\Harsh\Anaconda3\envs\myenv\lib\site-packages\django\db\models\query.py", line 1186, in _insert
    return query.get_compiler(using=using).execute_sql(return_id)
  File "C:\Users\Harsh\Anaconda3\envs\myenv\lib\site-packages\django\db\models\sql\compiler.py", line 1335, in execute_sql
    cursor.execute(sql, params)
  File "C:\Users\Harsh\Anaconda3\envs\myenv\lib\site-packages\django\db\backends\utils.py", line 99, in execute
    return super().execute(sql, params)
  File "C:\Users\Harsh\Anaconda3\envs\myenv\lib\site-packages\django\db\backends\utils.py", line 67, in execute
    return self._execute_with_wrappers(sql, params, many=False, executor=self._execute)
  File "C:\Users\Harsh\Anaconda3\envs\myenv\lib\site-packages\django\db\backends\utils.py", line 76, in _execute_with_wrappers
    return executor(sql, params, many, context)
  File "C:\Users\Harsh\Anaconda3\envs\myenv\lib\site-packages\django\db\backends\utils.py", line 84, in _execute
    return self.cursor.execute(sql, params)
  File "C:\Users\Harsh\Anaconda3\envs\myenv\lib\site-packages\django\db\utils.py", line 89, in __exit__
    raise dj_exc_value.with_traceback(traceback) from exc_value
  File "C:\Users\Harsh\Anaconda3\envs\myenv\lib\site-packages\django\db\backends\utils.py", line 84, in _execute
    return self.cursor.execute(sql, params)
  File "C:\Users\Harsh\Anaconda3\envs\myenv\lib\site-packages\django\db\backends\sqlite3\base.py", line 383, in execute
    return Database.Cursor.execute(self, query, params)
django.db.utils.IntegrityError: UNIQUE constraint failed: garbage_app_post.id
2019-09-27 12:45:24,551 - INFO - C:\Users\Harsh\PycharmProjects\sad_project\garbage_project\garbage_app\views.py changed, reloading.
2019-09-27 12:45:24,570 - INFO - C:\Users\Harsh\PycharmProjects\sad_project\garbage_project\garbage_app\views.py changed, reloading.
2019-09-27 12:45:35,860 - DEBUG - Data Received
2019-09-27 12:45:35,864 - DEBUG - 5
2019-09-27 12:45:35,864 - DEBUG - 5
2019-09-27 12:45:35,891 - CRITICAL - UNIQUE constraint failed: garbage_app_post.id
Traceback (most recent call last):
  File "C:\Users\Harsh\Anaconda3\envs\myenv\lib\site-packages\django\db\backends\utils.py", line 84, in _execute
    return self.cursor.execute(sql, params)
  File "C:\Users\Harsh\Anaconda3\envs\myenv\lib\site-packages\django\db\backends\sqlite3\base.py", line 383, in execute
    return Database.Cursor.execute(self, query, params)
sqlite3.IntegrityError: UNIQUE constraint failed: garbage_app_post.id

The above exception was the direct cause of the following exception:

Traceback (most recent call last):
  File "C:\Users\Harsh\PycharmProjects\sad_project\garbage_project\garbage_app\views.py", line 160, in upvote_view
    post_obj.save(["vote_count"])
  File "C:\Users\Harsh\Anaconda3\envs\myenv\lib\site-packages\django\db\models\base.py", line 741, in save
    force_update=force_update, update_fields=update_fields)
  File "C:\Users\Harsh\Anaconda3\envs\myenv\lib\site-packages\django\db\models\base.py", line 779, in save_base
    force_update, using, update_fields,
  File "C:\Users\Harsh\Anaconda3\envs\myenv\lib\site-packages\django\db\models\base.py", line 870, in _save_table
    result = self._do_insert(cls._base_manager, using, fields, update_pk, raw)
  File "C:\Users\Harsh\Anaconda3\envs\myenv\lib\site-packages\django\db\models\base.py", line 908, in _do_insert
    using=using, raw=raw)
  File "C:\Users\Harsh\Anaconda3\envs\myenv\lib\site-packages\django\db\models\manager.py", line 82, in manager_method
    return getattr(self.get_queryset(), name)(*args, **kwargs)
  File "C:\Users\Harsh\Anaconda3\envs\myenv\lib\site-packages\django\db\models\query.py", line 1186, in _insert
    return query.get_compiler(using=using).execute_sql(return_id)
  File "C:\Users\Harsh\Anaconda3\envs\myenv\lib\site-packages\django\db\models\sql\compiler.py", line 1335, in execute_sql
    cursor.execute(sql, params)
  File "C:\Users\Harsh\Anaconda3\envs\myenv\lib\site-packages\django\db\backends\utils.py", line 99, in execute
    return super().execute(sql, params)
  File "C:\Users\Harsh\Anaconda3\envs\myenv\lib\site-packages\django\db\backends\utils.py", line 67, in execute
    return self._execute_with_wrappers(sql, params, many=False, executor=self._execute)
  File "C:\Users\Harsh\Anaconda3\envs\myenv\lib\site-packages\django\db\backends\utils.py", line 76, in _execute_with_wrappers
    return executor(sql, params, many, context)
  File "C:\Users\Harsh\Anaconda3\envs\myenv\lib\site-packages\django\db\backends\utils.py", line 84, in _execute
    return self.cursor.execute(sql, params)
  File "C:\Users\Harsh\Anaconda3\envs\myenv\lib\site-packages\django\db\utils.py", line 89, in __exit__
    raise dj_exc_value.with_traceback(traceback) from exc_value
  File "C:\Users\Harsh\Anaconda3\envs\myenv\lib\site-packages\django\db\backends\utils.py", line 84, in _execute
    return self.cursor.execute(sql, params)
  File "C:\Users\Harsh\Anaconda3\envs\myenv\lib\site-packages\django\db\backends\sqlite3\base.py", line 383, in execute
    return Database.Cursor.execute(self, query, params)
django.db.utils.IntegrityError: UNIQUE constraint failed: garbage_app_post.id
2019-09-27 12:46:18,760 - INFO - C:\Users\Harsh\PycharmProjects\sad_project\garbage_project\garbage_app\views.py changed, reloading.
2019-09-27 12:46:18,780 - INFO - C:\Users\Harsh\PycharmProjects\sad_project\garbage_project\garbage_app\views.py changed, reloading.
2019-09-27 12:46:33,772 - INFO - C:\Users\Harsh\PycharmProjects\sad_project\garbage_project\garbage_app\views.py changed, reloading.
2019-09-27 12:46:33,777 - INFO - C:\Users\Harsh\PycharmProjects\sad_project\garbage_project\garbage_app\views.py changed, reloading.
2019-09-27 12:52:14,114 - INFO - C:\Users\Harsh\PycharmProjects\sad_project\garbage_project\garbage_app\views.py changed, reloading.
