2019-09-22 22:29:39,694 - INFO - C:\Users\bhavya\Desktop\sad_final\sad_project\garbage_project\garbage_app\views.py changed, reloading.
2019-09-22 22:29:41,050 - DEBUG - Hello world 
2019-09-22 22:30:24,534 - INFO - C:\Users\bhavya\Desktop\sad_final\sad_project\garbage_project\garbage_app\views.py changed, reloading.
2019-09-22 22:44:17,593 - INFO - C:\Users\bhavya\Desktop\sad_final\sad_project\garbage_project\garbage_app\views.py changed, reloading.
2019-09-22 22:44:34,371 - INFO - C:\Users\bhavya\Desktop\sad_final\sad_project\garbage_project\garbage_app\views.py changed, reloading.
2019-09-22 22:45:51,705 - INFO - C:\Users\bhavya\Desktop\sad_final\sad_project\garbage_project\garbage_app\views.py changed, reloading.
2019-09-22 22:46:09,915 - ERROR - Internal Server Error: /user/register/
Traceback (most recent call last):
  File "C:\Users\bhavya\Anaconda3\envs\myenv1\lib\site-packages\django\core\handlers\exception.py", line 34, in inner
    response = get_response(request)
  File "C:\Users\bhavya\Anaconda3\envs\myenv1\lib\site-packages\django\core\handlers\base.py", line 115, in _get_response
    response = self.process_exception_by_middleware(e, request)
  File "C:\Users\bhavya\Anaconda3\envs\myenv1\lib\site-packages\django\core\handlers\base.py", line 113, in _get_response
    response = wrapped_callback(request, *callback_args, **callback_kwargs)
  File "C:\Users\bhavya\Anaconda3\envs\myenv1\lib\site-packages\django\views\decorators\csrf.py", line 54, in wrapped_view
    return view_func(*args, **kwargs)
  File "C:\Users\bhavya\Anaconda3\envs\myenv1\lib\site-packages\django\views\generic\base.py", line 71, in view
    return self.dispatch(request, *args, **kwargs)
  File "C:\Users\bhavya\Anaconda3\envs\myenv1\lib\site-packages\rest_framework\views.py", line 497, in dispatch
    response = self.handle_exception(exc)
  File "C:\Users\bhavya\Anaconda3\envs\myenv1\lib\site-packages\rest_framework\views.py", line 457, in handle_exception
    self.raise_uncaught_exception(exc)
  File "C:\Users\bhavya\Anaconda3\envs\myenv1\lib\site-packages\rest_framework\views.py", line 468, in raise_uncaught_exception
    raise exc
  File "C:\Users\bhavya\Anaconda3\envs\myenv1\lib\site-packages\rest_framework\views.py", line 494, in dispatch
    response = handler(request, *args, **kwargs)
  File "C:\Users\bhavya\Anaconda3\envs\myenv1\lib\site-packages\rest_framework\decorators.py", line 50, in handler
    return func(*args, **kwargs)
  File "C:\Users\bhavya\Desktop\sad_final\sad_project\garbage_project\garbage_app\views.py", line 77, in Register_Garbage_User
    email=request.data[0]["email_id"]
KeyError: 0
2019-09-22 22:48:06,594 - ERROR - Internal Server Error: /user/register/
Traceback (most recent call last):
  File "C:\Users\bhavya\Anaconda3\envs\myenv1\lib\site-packages\django\core\handlers\exception.py", line 34, in inner
    response = get_response(request)
  File "C:\Users\bhavya\Anaconda3\envs\myenv1\lib\site-packages\django\core\handlers\base.py", line 115, in _get_response
    response = self.process_exception_by_middleware(e, request)
  File "C:\Users\bhavya\Anaconda3\envs\myenv1\lib\site-packages\django\core\handlers\base.py", line 113, in _get_response
    response = wrapped_callback(request, *callback_args, **callback_kwargs)
  File "C:\Users\bhavya\Anaconda3\envs\myenv1\lib\site-packages\django\views\decorators\csrf.py", line 54, in wrapped_view
    return view_func(*args, **kwargs)
  File "C:\Users\bhavya\Anaconda3\envs\myenv1\lib\site-packages\django\views\generic\base.py", line 71, in view
    return self.dispatch(request, *args, **kwargs)
  File "C:\Users\bhavya\Anaconda3\envs\myenv1\lib\site-packages\rest_framework\views.py", line 497, in dispatch
    response = self.handle_exception(exc)
  File "C:\Users\bhavya\Anaconda3\envs\myenv1\lib\site-packages\rest_framework\views.py", line 457, in handle_exception
    self.raise_uncaught_exception(exc)
  File "C:\Users\bhavya\Anaconda3\envs\myenv1\lib\site-packages\rest_framework\views.py", line 468, in raise_uncaught_exception
    raise exc
  File "C:\Users\bhavya\Anaconda3\envs\myenv1\lib\site-packages\rest_framework\views.py", line 494, in dispatch
    response = handler(request, *args, **kwargs)
  File "C:\Users\bhavya\Anaconda3\envs\myenv1\lib\site-packages\rest_framework\decorators.py", line 50, in handler
    return func(*args, **kwargs)
  File "C:\Users\bhavya\Desktop\sad_final\sad_project\garbage_project\garbage_app\views.py", line 77, in Register_Garbage_User
    email=request.data[0]["email_id"]
KeyError: 0
2019-09-22 22:50:32,632 - INFO - C:\Users\bhavya\Desktop\sad_final\sad_project\garbage_project\garbage_app\views.py changed, reloading.
2019-09-22 22:50:35,729 - ERROR - Internal Server Error: /user/register/
Traceback (most recent call last):
  File "C:\Users\bhavya\Anaconda3\envs\myenv1\lib\site-packages\django\core\handlers\exception.py", line 34, in inner
    response = get_response(request)
  File "C:\Users\bhavya\Anaconda3\envs\myenv1\lib\site-packages\django\core\handlers\base.py", line 115, in _get_response
    response = self.process_exception_by_middleware(e, request)
  File "C:\Users\bhavya\Anaconda3\envs\myenv1\lib\site-packages\django\core\handlers\base.py", line 113, in _get_response
    response = wrapped_callback(request, *callback_args, **callback_kwargs)
  File "C:\Users\bhavya\Anaconda3\envs\myenv1\lib\site-packages\django\views\decorators\csrf.py", line 54, in wrapped_view
    return view_func(*args, **kwargs)
  File "C:\Users\bhavya\Anaconda3\envs\myenv1\lib\site-packages\django\views\generic\base.py", line 71, in view
    return self.dispatch(request, *args, **kwargs)
  File "C:\Users\bhavya\Anaconda3\envs\myenv1\lib\site-packages\rest_framework\views.py", line 497, in dispatch
    response = self.handle_exception(exc)
  File "C:\Users\bhavya\Anaconda3\envs\myenv1\lib\site-packages\rest_framework\views.py", line 457, in handle_exception
    self.raise_uncaught_exception(exc)
  File "C:\Users\bhavya\Anaconda3\envs\myenv1\lib\site-packages\rest_framework\views.py", line 468, in raise_uncaught_exception
    raise exc
  File "C:\Users\bhavya\Anaconda3\envs\myenv1\lib\site-packages\rest_framework\views.py", line 494, in dispatch
    response = handler(request, *args, **kwargs)
  File "C:\Users\bhavya\Anaconda3\envs\myenv1\lib\site-packages\rest_framework\decorators.py", line 50, in handler
    return func(*args, **kwargs)
  File "C:\Users\bhavya\Desktop\sad_final\sad_project\garbage_project\garbage_app\views.py", line 77, in Register_Garbage_User
    email=request.data[0]["email_id"]
KeyError: 0
2019-09-22 22:55:34,210 - DEBUG - aman@gmailaa.com
2019-09-22 22:55:34,217 - DEBUG - Garbage_User object (3)
2019-09-22 23:06:45,741 - INFO - C:\Users\bhavya\Desktop\sad_final\sad_project\garbage_project\garbage_app\models.py changed, reloading.
2019-09-22 23:14:36,643 - INFO - C:\Users\bhavya\Desktop\sad_final\sad_project\garbage_project\garbage_app\views.py changed, reloading.
2019-09-23 17:23:54,407 - INFO - C:\Users\bhavya\Desktop\sad_final\sad_project\garbage_project\garbage_project\urls.py changed, reloading.
2019-09-23 17:26:53,326 - INFO - C:\Users\bhavya\Desktop\sad_final\sad_project\garbage_project\garbage_project\urls.py changed, reloading.
2019-09-23 17:27:04,719 - INFO - C:\Users\bhavya\Desktop\sad_final\sad_project\garbage_project\garbage_app\views.py changed, reloading.
2019-09-23 17:29:34,090 - WARNING - Bad Request: /postAPI/
